Workbook

Sheet Jun Act vs May Act
D1: program | E1: min Cnt | G1: Report
D2: f | E2: 100 | G2: CPR
D4: Actual | E4: 5 | F4: 6 | G4: 7 | H4: 8 | I4: 9 | J4: 10 | K4: 12 | L4: 14 | M4: 16 | N4: 18 | O4: 20 | P4: 24 | Q4: 30 | R4: 36 | S4: 42 | T4: 48 | U4: 54 | V4: 60 | W4: 72 | X4: 84 | Y4: 96 | Z4: 108 | AA4: 120 | AB4: 144 | AC4: 168 | AD4: 192 | AE4: 216 | AF4: 240 | AG4: 320 | AH4: 360
D5: 2000 | E5: =IF( E68>$E$2, SUMIFS(IF($G$2="CPR",'Grid Data'!$V$4:$V$2342,'Grid Data'!$W$4:$W$2342),'Grid Data'!$N$4:$N$2342,$D5,'Grid Data'!$O$4:$O$2342,E$4,'Grid Data'!$M$4:$M$2342,$D$2)*100, 0) -> 0 | F5: =IF( F68>$E$2, SUMIFS(IF($G$2="CPR",'Grid Data'!$V$4:$V$2342,'Grid Data'!$W$4:$W$2342),'Grid Data'!$N$4:$N$2342,$D5,'Grid Data'!$O$4:$O$2342,F$4,'Grid Data'!$M$4:$M$2342,$D$2)*100, 0) -> 0 | G5: =IF( G68>$E$2, SUMIFS(IF($G$2="CPR",'Grid Data'!$V$4:$V$2342,'Grid Data'!$W$4:$W$2342),'Grid Data'!$N$4:$N$2342,$D5,'Grid Data'!$O$4:$O$2342,G$4,'Grid Data'!$M$4:$M$2342,$D$2)*100, 0) -> 0 | H5: =IF( H68>$E$2, SUMIFS(IF($G$2="CPR",'Grid Data'!$V$4:$V$2342,'Grid Data'!$W$4:$W$2342),'Grid Data'!$N$4:$N$2342,$D5,'Grid Data'!$O$4:$O$2342,H$4,'Grid Data'!$M$4:$M$2342,$D$2)*100, 0) -> 0 | I5: =IF( I68>$E$2, SUMIFS(IF($G$2="CPR",'Grid Data'!$V$4:$V$2342,'Grid Data'!$W$4:$W$2342),'Grid Data'!$N$4:$N$2342,$D5,'Grid Data'!$O$4:$O$2342,I$4,'Grid Data'!$M$4:$M$2342,$D$2)*100, 0) -> 0 | J5: =IF( J68>$E$2, SUMIFS(IF($G$2="CPR",'Grid Data'!$V$4:$V$2342,'Grid Data'!$W$4:$W$2342),'Grid Data'!$N$4:$N$2342,$D5,'Grid Data'!$O$4:$O$2342,J$4,'Grid Data'!$M$4:$M$2342,$D$2)*100, 0) -> 0 | K5: =IF( K68>$E$2, SUMIFS(IF($G$2="CPR",'Grid Data'!$V$4:$V$2342,'Grid Data'!$W$4:$W$2342),'Grid Data'!$N$4:$N$2342,$D5,'Grid Data'!$O$4:$O$2342,K$4,'Grid Data'!$M$4:$M$2342,$D$2)*100, 0) -> 0 | L5: =IF( L68>$E$2, SUMIFS(IF($G$2="CPR",'Grid Data'!$V$4:$V$2342,'Grid Data'!$W$4:$W$2342),'Grid Data'!$N$4:$N$2342,$D5,'Grid Data'!$O$4:$O$2342,L$4,'Grid Data'!$M$4:$M$2342,$D$2)*100, 0) -> 0 | ... AH5: =IF( AH68>$E$2, SUMIFS(IF($G$2="CPR",'Grid Data'!$V$4:$V$2342,'Grid Data'!$W$4:$W$2342),'Grid Data'!$N$4:$N$2342,$D5,'Grid Data'!$O$4:$O$2342,AH$4,'Grid Data'!$M$4:$M$2342,$D$2)*100, 0) -> 0
D6: 2250 | E6: =IF( E69>$E$2, SUMIFS(IF($G$2="CPR",'Grid Data'!$V$4:$V$2342,'Grid Data'!$W$4:$W$2342),'Grid Data'!$N$4:$N$2342,$D6,'Grid Data'!$O$4:$O$2342,E$4,'Grid Data'!$M$4:$M$2342,$D$2)*100, 0) -> 0 | F6: =IF( F69>$E$2, SUMIFS(IF($G$2="CPR",'Grid Data'!$V$4:$V$2342,'Grid Data'!$W$4:$W$2342),'Grid Data'!$N$4:$N$2342,$D6,'Grid Data'!$O$4:$O$2342,F$4,'Grid Data'!$M$4:$M$2342,$D$2)*100, 0) -> 0 | G6: =IF( G69>$E$2, SUMIFS(IF($G$2="CPR",'Grid Data'!$V$4:$V$2342,'Grid Data'!$W$4:$W$2342),'Grid Data'!$N$4:$N$2342,$D6,'Grid Data'!$O$4:$O$2342,G$4,'Grid Data'!$M$4:$M$2342,$D$2)*100, 0) -> 0 | H6: =IF( H69>$E$2, SUMIFS(IF($G$2="CPR",'Grid Data'!$V$4:$V$2342,'Grid Data'!$W$4:$W$2342),'Grid Data'!$N$4:$N$2342,$D6,'Grid Data'!$O$4:$O$2342,H$4,'Grid Data'!$M$4:$M$2342,$D$2)*100, 0) -> 0 | I6: =IF( I69>$E$2, SUMIFS(IF($G$2="CPR",'Grid Data'!$V$4:$V$2342,'Grid Data'!$W$4:$W$2342),'Grid Data'!$N$4:$N$2342,$D6,'Grid Data'!$O$4:$O$2342,I$4,'Grid Data'!$M$4:$M$2342,$D$2)*100, 0) -> 0 | J6: =IF( J69>$E$2, SUMIFS(IF($G$2="CPR",'Grid Data'!$V$4:$V$2342,'Grid Data'!$W$4:$W$2342),'Grid Data'!$N$4:$N$2342,$D6,'Grid Data'!$O$4:$O$2342,J$4,'Grid Data'!$M$4:$M$2342,$D$2)*100, 0) -> 0 | K6: =IF( K69>$E$2, SUMIFS(IF($G$2="CPR",'Grid Data'!$V$4:$V$2342,'Grid Data'!$W$4:$W$2342),'Grid Data'!$N$4:$N$2342,$D6,'Grid Data'!$O$4:$O$2342,K$4,'Grid Data'!$M$4:$M$2342,$D$2)*100, 0) -> 0 | L6: =IF( L69>$E$2, SUMIFS(IF($G$2="CPR",'Grid Data'!$V$4:$V$2342,'Grid Data'!$W$4:$W$2342),'Grid Data'!$N$4:$N$2342,$D6,'Grid Data'!$O$4:$O$2342,L$4,'Grid Data'!$M$4:$M$2342,$D$2)*100, 0) -> 0 | ... AH6: =IF( AH69>$E$2, SUMIFS(IF($G$2="CPR",'Grid Data'!$V$4:$V$2342,'Grid Data'!$W$4:$W$2342),'Grid Data'!$N$4:$N$2342,$D6,'Grid Data'!$O$4:$O$2342,AH$4,'Grid Data'!$M$4:$M$2342,$D$2)*100, 0) -> 0
D7: 2500 | E7: =IF( E70>$E$2, SUMIFS(IF($G$2="CPR",'Grid Data'!$V$4:$V$2342,'Grid Data'!$W$4:$W$2342),'Grid Data'!$N$4:$N$2342,$D7,'Grid Data'!$O$4:$O$2342,E$4,'Grid Data'!$M$4:$M$2342,$D$2)*100, 0) -> 0 | F7: =IF( F70>$E$2, SUMIFS(IF($G$2="CPR",'Grid Data'!$V$4:$V$2342,'Grid Data'!$W$4:$W$2342),'Grid Data'!$N$4:$N$2342,$D7,'Grid Data'!$O$4:$O$2342,F$4,'Grid Data'!$M$4:$M$2342,$D$2)*100, 0) -> 0 | G7: =IF( G70>$E$2, SUMIFS(IF($G$2="CPR",'Grid Data'!$V$4:$V$2342,'Grid Data'!$W$4:$W$2342),'Grid Data'!$N$4:$N$2342,$D7,'Grid Data'!$O$4:$O$2342,G$4,'Grid Data'!$M$4:$M$2342,$D$2)*100, 0) -> 0 | H7: =IF( H70>$E$2, SUMIFS(IF($G$2="CPR",'Grid Data'!$V$4:$V$2342,'Grid Data'!$W$4:$W$2342),'Grid Data'!$N$4:$N$2342,$D7,'Grid Data'!$O$4:$O$2342,H$4,'Grid Data'!$M$4:$M$2342,$D$2)*100, 0) -> 0 | I7: =IF( I70>$E$2, SUMIFS(IF($G$2="CPR",'Grid Data'!$V$4:$V$2342,'Grid Data'!$W$4:$W$2342),'Grid Data'!$N$4:$N$2342,$D7,'Grid Data'!$O$4:$O$2342,I$4,'Grid Data'!$M$4:$M$2342,$D$2)*100, 0) -> 0 | J7: =IF( J70>$E$2, SUMIFS(IF($G$2="CPR",'Grid Data'!$V$4:$V$2342,'Grid Data'!$W$4:$W$2342),'Grid Data'!$N$4:$N$2342,$D7,'Grid Data'!$O$4:$O$2342,J$4,'Grid Data'!$M$4:$M$2342,$D$2)*100, 0) -> 0 | K7: =IF( K70>$E$2, SUMIFS(IF($G$2="CPR",'Grid Data'!$V$4:$V$2342,'Grid Data'!$W$4:$W$2342),'Grid Data'!$N$4:$N$2342,$D7,'Grid Data'!$O$4:$O$2342,K$4,'Grid Data'!$M$4:$M$2342,$D$2)*100, 0) -> 0 | L7: =IF( L70>$E$2, SUMIFS(IF($G$2="CPR",'Grid Data'!$V$4:$V$2342,'Grid Data'!$W$4:$W$2342),'Grid Data'!$N$4:$N$2342,$D7,'Grid Data'!$O$4:$O$2342,L$4,'Grid Data'!$M$4:$M$2342,$D$2)*100, 0) -> 0 | ... AH7: =IF( AH70>$E$2, SUMIFS(IF($G$2="CPR",'Grid Data'!$V$4:$V$2342,'Grid Data'!$W$4:$W$2342),'Grid Data'!$N$4:$N$2342,$D7,'Grid Data'!$O$4:$O$2342,AH$4,'Grid Data'!$M$4:$M$2342,$D$2)*100, 0) -> 0
D8: 2750 | E8: =IF( E71>$E$2, SUMIFS(IF($G$2="CPR",'Grid Data'!$V$4:$V$2342,'Grid Data'!$W$4:$W$2342),'Grid Data'!$N$4:$N$2342,$D8,'Grid Data'!$O$4:$O$2342,E$4,'Grid Data'!$M$4:$M$2342,$D$2)*100, 0) -> 0 | F8: =IF( F71>$E$2, SUMIFS(IF($G$2="CPR",'Grid Data'!$V$4:$V$2342,'Grid Data'!$W$4:$W$2342),'Grid Data'!$N$4:$N$2342,$D8,'Grid Data'!$O$4:$O$2342,F$4,'Grid Data'!$M$4:$M$2342,$D$2)*100, 0) -> 0 | G8: =IF( G71>$E$2, SUMIFS(IF($G$2="CPR",'Grid Data'!$V$4:$V$2342,'Grid Data'!$W$4:$W$2342),'Grid Data'!$N$4:$N$2342,$D8,'Grid Data'!$O$4:$O$2342,G$4,'Grid Data'!$M$4:$M$2342,$D$2)*100, 0) -> 0 | H8: =IF( H71>$E$2, SUMIFS(IF($G$2="CPR",'Grid Data'!$V$4:$V$2342,'Grid Data'!$W$4:$W$2342),'Grid Data'!$N$4:$N$2342,$D8,'Grid Data'!$O$4:$O$2342,H$4,'Grid Data'!$M$4:$M$2342,$D$2)*100, 0) -> 0 | I8: =IF( I71>$E$2, SUMIFS(IF($G$2="CPR",'Grid Data'!$V$4:$V$2342,'Grid Data'!$W$4:$W$2342),'Grid Data'!$N$4:$N$2342,$D8,'Grid Data'!$O$4:$O$2342,I$4,'Grid Data'!$M$4:$M$2342,$D$2)*100, 0) -> 0 | J8: =IF( J71>$E$2, SUMIFS(IF($G$2="CPR",'Grid Data'!$V$4:$V$2342,'Grid Data'!$W$4:$W$2342),'Grid Data'!$N$4:$N$2342,$D8,'Grid Data'!$O$4:$O$2342,J$4,'Grid Data'!$M$4:$M$2342,$D$2)*100, 0) -> 0 | K8: =IF( K71>$E$2, SUMIFS(IF($G$2="CPR",'Grid Data'!$V$4:$V$2342,'Grid Data'!$W$4:$W$2342),'Grid Data'!$N$4:$N$2342,$D8,'Grid Data'!$O$4:$O$2342,K$4,'Grid Data'!$M$4:$M$2342,$D$2)*100, 0) -> 0 | L8: =IF( L71>$E$2, SUMIFS(IF($G$2="CPR",'Grid Data'!$V$4:$V$2342,'Grid Data'!$W$4:$W$2342),'Grid Data'!$N$4:$N$2342,$D8,'Grid Data'!$O$4:$O$2342,L$4,'Grid Data'!$M$4:$M$2342,$D$2)*100, 0) -> 0 | ... AH8: =IF( AH71>$E$2, SUMIFS(IF($G$2="CPR",'Grid Data'!$V$4:$V$2342,'Grid Data'!$W$4:$W$2342),'Grid Data'!$N$4:$N$2342,$D8,'Grid Data'!$O$4:$O$2342,AH$4,'Grid Data'!$M$4:$M$2342,$D$2)*100, 0) -> 0
D9: 3000 | E9: =IF( E72>$E$2, SUMIFS(IF($G$2="CPR",'Grid Data'!$V$4:$V$2342,'Grid Data'!$W$4:$W$2342),'Grid Data'!$N$4:$N$2342,$D9,'Grid Data'!$O$4:$O$2342,E$4,'Grid Data'!$M$4:$M$2342,$D$2)*100, 0) -> 0 | F9: =IF( F72>$E$2, SUMIFS(IF($G$2="CPR",'Grid Data'!$V$4:$V$2342,'Grid Data'!$W$4:$W$2342),'Grid Data'!$N$4:$N$2342,$D9,'Grid Data'!$O$4:$O$2342,F$4,'Grid Data'!$M$4:$M$2342,$D$2)*100, 0) -> 0 | G9: =IF( G72>$E$2, SUMIFS(IF($G$2="CPR",'Grid Data'!$V$4:$V$2342,'Grid Data'!$W$4:$W$2342),'Grid Data'!$N$4:$N$2342,$D9,'Grid Data'!$O$4:$O$2342,G$4,'Grid Data'!$M$4:$M$2342,$D$2)*100, 0) -> 0 | H9: =IF( H72>$E$2, SUMIFS(IF($G$2="CPR",'Grid Data'!$V$4:$V$2342,'Grid Data'!$W$4:$W$2342),'Grid Data'!$N$4:$N$2342,$D9,'Grid Data'!$O$4:$O$2342,H$4,'Grid Data'!$M$4:$M$2342,$D$2)*100, 0) -> 0 | I9: =IF( I72>$E$2, SUMIFS(IF($G$2="CPR",'Grid Data'!$V$4:$V$2342,'Grid Data'!$W$4:$W$2342),'Grid Data'!$N$4:$N$2342,$D9,'Grid Data'!$O$4:$O$2342,I$4,'Grid Data'!$M$4:$M$2342,$D$2)*100, 0) -> 0 | J9: =IF( J72>$E$2, SUMIFS(IF($G$2="CPR",'Grid Data'!$V$4:$V$2342,'Grid Data'!$W$4:$W$2342),'Grid Data'!$N$4:$N$2342,$D9,'Grid Data'!$O$4:$O$2342,J$4,'Grid Data'!$M$4:$M$2342,$D$2)*100, 0) -> 0 | K9: =IF( K72>$E$2, SUMIFS(IF($G$2="CPR",'Grid Data'!$V$4:$V$2342,'Grid Data'!$W$4:$W$2342),'Grid Data'!$N$4:$N$2342,$D9,'Grid Data'!$O$4:$O$2342,K$4,'Grid Data'!$M$4:$M$2342,$D$2)*100, 0) -> 0 | L9: =IF( L72>$E$2, SUMIFS(IF($G$2="CPR",'Grid Data'!$V$4:$V$2342,'Grid Data'!$W$4:$W$2342),'Grid Data'!$N$4:$N$2342,$D9,'Grid Data'!$O$4:$O$2342,L$4,'Grid Data'!$M$4:$M$2342,$D$2)*100, 0) -> 0 | ... AH9: =IF( AH72>$E$2, SUMIFS(IF($G$2="CPR",'Grid Data'!$V$4:$V$2342,'Grid Data'!$W$4:$W$2342),'Grid Data'!$N$4:$N$2342,$D9,'Grid Data'!$O$4:$O$2342,AH$4,'Grid Data'!$M$4:$M$2342,$D$2)*100, 0) -> 0
D10: 3250 | E10: =IF( E73>$E$2, SUMIFS(IF($G$2="CPR",'Grid Data'!$V$4:$V$2342,'Grid Data'!$W$4:$W$2342),'Grid Data'!$N$4:$N$2342,$D10,'Grid Data'!$O$4:$O$2342,E$4,'Grid Data'!$M$4:$M$2342,$D$2)*100, 0) -> 0 | F10: =IF( F73>$E$2, SUMIFS(IF($G$2="CPR",'Grid Data'!$V$4:$V$2342,'Grid Data'!$W$4:$W$2342),'Grid Data'!$N$4:$N$2342,$D10,'Grid Data'!$O$4:$O$2342,F$4,'Grid Data'!$M$4:$M$2342,$D$2)*100, 0) -> 0 | G10: =IF( G73>$E$2, SUMIFS(IF($G$2="CPR",'Grid Data'!$V$4:$V$2342,'Grid Data'!$W$4:$W$2342),'Grid Data'!$N$4:$N$2342,$D10,'Grid Data'!$O$4:$O$2342,G$4,'Grid Data'!$M$4:$M$2342,$D$2)*100, 0) -> 0 | H10: =IF( H73>$E$2, SUMIFS(IF($G$2="CPR",'Grid Data'!$V$4:$V$2342,'Grid Data'!$W$4:$W$2342),'Grid Data'!$N$4:$N$2342,$D10,'Grid Data'!$O$4:$O$2342,H$4,'Grid Data'!$M$4:$M$2342,$D$2)*100, 0) -> 0 | I10: =IF( I73>$E$2, SUMIFS(IF($G$2="CPR",'Grid Data'!$V$4:$V$2342,'Grid Data'!$W$4:$W$2342),'Grid Data'!$N$4:$N$2342,$D10,'Grid Data'!$O$4:$O$2342,I$4,'Grid Data'!$M$4:$M$2342,$D$2)*100, 0) -> 0 | J10: =IF( J73>$E$2, SUMIFS(IF($G$2="CPR",'Grid Data'!$V$4:$V$2342,'Grid Data'!$W$4:$W$2342),'Grid Data'!$N$4:$N$2342,$D10,'Grid Data'!$O$4:$O$2342,J$4,'Grid Data'!$M$4:$M$2342,$D$2)*100, 0) -> 0 | K10: =IF( K73>$E$2, SUMIFS(IF($G$2="CPR",'Grid Data'!$V$4:$V$2342,'Grid Data'!$W$4:$W$2342),'Grid Data'!$N$4:$N$2342,$D10,'Grid Data'!$O$4:$O$2342,K$4,'Grid Data'!$M$4:$M$2342,$D$2)*100, 0) -> 0 | L10: =IF( L73>$E$2, SUMIFS(IF($G$2="CPR",'Grid Data'!$V$4:$V$2342,'Grid Data'!$W$4:$W$2342),'Grid Data'!$N$4:$N$2342,$D10,'Grid Data'!$O$4:$O$2342,L$4,'Grid Data'!$M$4:$M$2342,$D$2)*100, 0) -> 0 | ... AH10: =IF( AH73>$E$2, SUMIFS(IF($G$2="CPR",'Grid Data'!$V$4:$V$2342,'Grid Data'!$W$4:$W$2342),'Grid Data'!$N$4:$N$2342,$D10,'Grid Data'!$O$4:$O$2342,AH$4,'Grid Data'!$M$4:$M$2342,$D$2)*100, 0) -> 0
D11: 3500 | E11: =IF( E74>$E$2, SUMIFS(IF($G$2="CPR",'Grid Data'!$V$4:$V$2342,'Grid Data'!$W$4:$W$2342),'Grid Data'!$N$4:$N$2342,$D11,'Grid Data'!$O$4:$O$2342,E$4,'Grid Data'!$M$4:$M$2342,$D$2)*100, 0) -> 0 | F11: =IF( F74>$E$2, SUMIFS(IF($G$2="CPR",'Grid Data'!$V$4:$V$2342,'Grid Data'!$W$4:$W$2342),'Grid Data'!$N$4:$N$2342,$D11,'Grid Data'!$O$4:$O$2342,F$4,'Grid Data'!$M$4:$M$2342,$D$2)*100, 0) -> 0 | G11: =IF( G74>$E$2, SUMIFS(IF($G$2="CPR",'Grid Data'!$V$4:$V$2342,'Grid Data'!$W$4:$W$2342),'Grid Data'!$N$4:$N$2342,$D11,'Grid Data'!$O$4:$O$2342,G$4,'Grid Data'!$M$4:$M$2342,$D$2)*100, 0) -> 0 | H11: =IF( H74>$E$2, SUMIFS(IF($G$2="CPR",'Grid Data'!$V$4:$V$2342,'Grid Data'!$W$4:$W$2342),'Grid Data'!$N$4:$N$2342,$D11,'Grid Data'!$O$4:$O$2342,H$4,'Grid Data'!$M$4:$M$2342,$D$2)*100, 0) -> 0 | I11: =IF( I74>$E$2, SUMIFS(IF($G$2="CPR",'Grid Data'!$V$4:$V$2342,'Grid Data'!$W$4:$W$2342),'Grid Data'!$N$4:$N$2342,$D11,'Grid Data'!$O$4:$O$2342,I$4,'Grid Data'!$M$4:$M$2342,$D$2)*100, 0) -> 0 | J11: =IF( J74>$E$2, SUMIFS(IF($G$2="CPR",'Grid Data'!$V$4:$V$2342,'Grid Data'!$W$4:$W$2342),'Grid Data'!$N$4:$N$2342,$D11,'Grid Data'!$O$4:$O$2342,J$4,'Grid Data'!$M$4:$M$2342,$D$2)*100, 0) -> 0 | K11: =IF( K74>$E$2, SUMIFS(IF($G$2="CPR",'Grid Data'!$V$4:$V$2342,'Grid Data'!$W$4:$W$2342),'Grid Data'!$N$4:$N$2342,$D11,'Grid Data'!$O$4:$O$2342,K$4,'Grid Data'!$M$4:$M$2342,$D$2)*100, 0) -> 0 | L11: =IF( L74>$E$2, SUMIFS(IF($G$2="CPR",'Grid Data'!$V$4:$V$2342,'Grid Data'!$W$4:$W$2342),'Grid Data'!$N$4:$N$2342,$D11,'Grid Data'!$O$4:$O$2342,L$4,'Grid Data'!$M$4:$M$2342,$D$2)*100, 0) -> 0 | ... AH11: =IF( AH74>$E$2, SUMIFS(IF($G$2="CPR",'Grid Data'!$V$4:$V$2342,'Grid Data'!$W$4:$W$2342),'Grid Data'!$N$4:$N$2342,$D11,'Grid Data'!$O$4:$O$2342,AH$4,'Grid Data'!$M$4:$M$2342,$D$2)*100, 0) -> 0
D12: 3750 | E12: =IF( E75>$E$2, SUMIFS(IF($G$2="CPR",'Grid Data'!$V$4:$V$2342,'Grid Data'!$W$4:$W$2342),'Grid Data'!$N$4:$N$2342,$D12,'Grid Data'!$O$4:$O$2342,E$4,'Grid Data'!$M$4:$M$2342,$D$2)*100, 0) -> 0 | F12: =IF( F75>$E$2, SUMIFS(IF($G$2="CPR",'Grid Data'!$V$4:$V$2342,'Grid Data'!$W$4:$W$2342),'Grid Data'!$N$4:$N$2342,$D12,'Grid Data'!$O$4:$O$2342,F$4,'Grid Data'!$M$4:$M$2342,$D$2)*100, 0) -> 0 | G12: =IF( G75>$E$2, SUMIFS(IF($G$2="CPR",'Grid Data'!$V$4:$V$2342,'Grid Data'!$W$4:$W$2342),'Grid Data'!$N$4:$N$2342,$D12,'Grid Data'!$O$4:$O$2342,G$4,'Grid Data'!$M$4:$M$2342,$D$2)*100, 0) -> 0 | H12: =IF( H75>$E$2, SUMIFS(IF($G$2="CPR",'Grid Data'!$V$4:$V$2342,'Grid Data'!$W$4:$W$2342),'Grid Data'!$N$4:$N$2342,$D12,'Grid Data'!$O$4:$O$2342,H$4,'Grid Data'!$M$4:$M$2342,$D$2)*100, 0) -> 0 | I12: =IF( I75>$E$2, SUMIFS(IF($G$2="CPR",'Grid Data'!$V$4:$V$2342,'Grid Data'!$W$4:$W$2342),'Grid Data'!$N$4:$N$2342,$D12,'Grid Data'!$O$4:$O$2342,I$4,'Grid Data'!$M$4:$M$2342,$D$2)*100, 0) -> 0 | J12: =IF( J75>$E$2, SUMIFS(IF($G$2="CPR",'Grid Data'!$V$4:$V$2342,'Grid Data'!$W$4:$W$2342),'Grid Data'!$N$4:$N$2342,$D12,'Grid Data'!$O$4:$O$2342,J$4,'Grid Data'!$M$4:$M$2342,$D$2)*100, 0) -> 0 | K12: =IF( K75>$E$2, SUMIFS(IF($G$2="CPR",'Grid Data'!$V$4:$V$2342,'Grid Data'!$W$4:$W$2342),'Grid Data'!$N$4:$N$2342,$D12,'Grid Data'!$O$4:$O$2342,K$4,'Grid Data'!$M$4:$M$2342,$D$2)*100, 0) -> 0 | L12: =IF( L75>$E$2, SUMIFS(IF($G$2="CPR",'Grid Data'!$V$4:$V$2342,'Grid Data'!$W$4:$W$2342),'Grid Data'!$N$4:$N$2342,$D12,'Grid Data'!$O$4:$O$2342,L$4,'Grid Data'!$M$4:$M$2342,$D$2)*100, 0) -> 0 | ... AH12: =IF( AH75>$E$2, SUMIFS(IF($G$2="CPR",'Grid Data'!$V$4:$V$2342,'Grid Data'!$W$4:$W$2342),'Grid Data'!$N$4:$N$2342,$D12,'Grid Data'!$O$4:$O$2342,AH$4,'Grid Data'!$M$4:$M$2342,$D$2)*100, 0) -> 0
D13: 4000 | E13: =IF( E76>$E$2, SUMIFS(IF($G$2="CPR",'Grid Data'!$V$4:$V$2342,'Grid Data'!$W$4:$W$2342),'Grid Data'!$N$4:$N$2342,$D13,'Grid Data'!$O$4:$O$2342,E$4,'Grid Data'!$M$4:$M$2342,$D$2)*100, 0) -> 0.1397 | F13: =IF( F76>$E$2, SUMIFS(IF($G$2="CPR",'Grid Data'!$V$4:$V$2342,'Grid Data'!$W$4:$W$2342),'Grid Data'!$N$4:$N$2342,$D13,'Grid Data'!$O$4:$O$2342,F$4,'Grid Data'!$M$4:$M$2342,$D$2)*100, 0) -> 0 | G13: =IF( G76>$E$2, SUMIFS(IF($G$2="CPR",'Grid Data'!$V$4:$V$2342,'Grid Data'!$W$4:$W$2342),'Grid Data'!$N$4:$N$2342,$D13,'Grid Data'!$O$4:$O$2342,G$4,'Grid Data'!$M$4:$M$2342,$D$2)*100, 0) -> 0 | H13: =IF( H76>$E$2, SUMIFS(IF($G$2="CPR",'Grid Data'!$V$4:$V$2342,'Grid Data'!$W$4:$W$2342),'Grid Data'!$N$4:$N$2342,$D13,'Grid Data'!$O$4:$O$2342,H$4,'Grid Data'!$M$4:$M$2342,$D$2)*100, 0) -> 0.5643 | I13: =IF( I76>$E$2, SUMIFS(IF($G$2="CPR",'Grid Data'!$V$4:$V$2342,'Grid Data'!$W$4:$W$2342),'Grid Data'!$N$4:$N$2342,$D13,'Grid Data'!$O$4:$O$2342,I$4,'Grid Data'!$M$4:$M$2342,$D$2)*100, 0) -> 1.2577 | J13: =IF( J76>$E$2, SUMIFS(IF($G$2="CPR",'Grid Data'!$V$4:$V$2342,'Grid Data'!$W$4:$W$2342),'Grid Data'!$N$4:$N$2342,$D13,'Grid Data'!$O$4:$O$2342,J$4,'Grid Data'!$M$4:$M$2342,$D$2)*100, 0) -> 0 | K13: =IF( K76>$E$2, SUMIFS(IF($G$2="CPR",'Grid Data'!$V$4:$V$2342,'Grid Data'!$W$4:$W$2342),'Grid Data'!$N$4:$N$2342,$D13,'Grid Data'!$O$4:$O$2342,K$4,'Grid Data'!$M$4:$M$2342,$D$2)*100, 0) -> 0 | L13: =IF( L76>$E$2, SUMIFS(IF($G$2="CPR",'Grid Data'!$V$4:$V$2342,'Grid Data'!$W$4:$W$2342),'Grid Data'!$N$4:$N$2342,$D13,'Grid Data'!$O$4:$O$2342,L$4,'Grid Data'!$M$4:$M$2342,$D$2)*100, 0) -> 0 | ... AH13: =IF( AH76>$E$2, SUMIFS(IF($G$2="CPR",'Grid Data'!$V$4:$V$2342,'Grid Data'!$W$4:$W$2342),'Grid Data'!$N$4:$N$2342,$D13,'Grid Data'!$O$4:$O$2342,AH$4,'Grid Data'!$M$4:$M$2342,$D$2)*100, 0) -> 0
D14: 4250 | E14: =IF( E77>$E$2, SUMIFS(IF($G$2="CPR",'Grid Data'!$V$4:$V$2342,'Grid Data'!$W$4:$W$2342),'Grid Data'!$N$4:$N$2342,$D14,'Grid Data'!$O$4:$O$2342,E$4,'Grid Data'!$M$4:$M$2342,$D$2)*100, 0) -> 0 | F14: =IF( F77>$E$2, SUMIFS(IF($G$2="CPR",'Grid Data'!$V$4:$V$2342,'Grid Data'!$W$4:$W$2342),'Grid Data'!$N$4:$N$2342,$D14,'Grid Data'!$O$4:$O$2342,F$4,'Grid Data'!$M$4:$M$2342,$D$2)*100, 0) -> 0 | G14: =IF( G77>$E$2, SUMIFS(IF($G$2="CPR",'Grid Data'!$V$4:$V$2342,'Grid Data'!$W$4:$W$2342),'Grid Data'!$N$4:$N$2342,$D14,'Grid Data'!$O$4:$O$2342,G$4,'Grid Data'!$M$4:$M$2342,$D$2)*100, 0) -> 0 | H14: =IF( H77>$E$2, SUMIFS(IF($G$2="CPR",'Grid Data'!$V$4:$V$2342,'Grid Data'!$W$4:$W$2342),'Grid Data'!$N$4:$N$2342,$D14,'Grid Data'!$O$4:$O$2342,H$4,'Grid Data'!$M$4:$M$2342,$D$2)*100, 0) -> 0 | I14: =IF( I77>$E$2, SUMIFS(IF($G$2="CPR",'Grid Data'!$V$4:$V$2342,'Grid Data'!$W$4:$W$2342),'Grid Data'!$N$4:$N$2342,$D14,'Grid Data'!$O$4:$O$2342,I$4,'Grid Data'!$M$4:$M$2342,$D$2)*100, 0) -> 0 | J14: =IF( J77>$E$2, SUMIFS(IF($G$2="CPR",'Grid Data'!$V$4:$V$2342,'Grid Data'!$W$4:$W$2342),'Grid Data'!$N$4:$N$2342,$D14,'Grid Data'!$O$4:$O$2342,J$4,'Grid Data'!$M$4:$M$2342,$D$2)*100, 0) -> 0 | K14: =IF( K77>$E$2, SUMIFS(IF($G$2="CPR",'Grid Data'!$V$4:$V$2342,'Grid Data'!$W$4:$W$2342),'Grid Data'!$N$4:$N$2342,$D14,'Grid Data'!$O$4:$O$2342,K$4,'Grid Data'!$M$4:$M$2342,$D$2)*100, 0) -> 0 | L14: =IF( L77>$E$2, SUMIFS(IF($G$2="CPR",'Grid Data'!$V$4:$V$2342,'Grid Data'!$W$4:$W$2342),'Grid Data'!$N$4:$N$2342,$D14,'Grid Data'!$O$4:$O$2342,L$4,'Grid Data'!$M$4:$M$2342,$D$2)*100, 0) -> 0 | ... AH14: =IF( AH77>$E$2, SUMIFS(IF($G$2="CPR",'Grid Data'!$V$4:$V$2342,'Grid Data'!$W$4:$W$2342),'Grid Data'!$N$4:$N$2342,$D14,'Grid Data'!$O$4:$O$2342,AH$4,'Grid Data'!$M$4:$M$2342,$D$2)*100, 0) -> 0
D15: 4500 | E15: =IF( E78>$E$2, SUMIFS(IF($G$2="CPR",'Grid Data'!$V$4:$V$2342,'Grid Data'!$W$4:$W$2342),'Grid Data'!$N$4:$N$2342,$D15,'Grid Data'!$O$4:$O$2342,E$4,'Grid Data'!$M$4:$M$2342,$D$2)*100, 0) -> 0 | F15: =IF( F78>$E$2, SUMIFS(IF($G$2="CPR",'Grid Data'!$V$4:$V$2342,'Grid Data'!$W$4:$W$2342),'Grid Data'!$N$4:$N$2342,$D15,'Grid Data'!$O$4:$O$2342,F$4,'Grid Data'!$M$4:$M$2342,$D$2)*100, 0) -> 2.4293 | G15: =IF( G78>$E$2, SUMIFS(IF($G$2="CPR",'Grid Data'!$V$4:$V$2342,'Grid Data'!$W$4:$W$2342),'Grid Data'!$N$4:$N$2342,$D15,'Grid Data'!$O$4:$O$2342,G$4,'Grid Data'!$M$4:$M$2342,$D$2)*100, 0) -> 0 | H15: =IF( H78>$E$2, SUMIFS(IF($G$2="CPR",'Grid Data'!$V$4:$V$2342,'Grid Data'!$W$4:$W$2342),'Grid Data'!$N$4:$N$2342,$D15,'Grid Data'!$O$4:$O$2342,H$4,'Grid Data'!$M$4:$M$2342,$D$2)*100, 0) -> 0 | I15: =IF( I78>$E$2, SUMIFS(IF($G$2="CPR",'Grid Data'!$V$4:$V$2342,'Grid Data'!$W$4:$W$2342),'Grid Data'!$N$4:$N$2342,$D15,'Grid Data'!$O$4:$O$2342,I$4,'Grid Data'!$M$4:$M$2342,$D$2)*100, 0) -> 0 | J15: =IF( J78>$E$2, SUMIFS(IF($G$2="CPR",'Grid Data'!$V$4:$V$2342,'Grid Data'!$W$4:$W$2342),'Grid Data'!$N$4:$N$2342,$D15,'Grid Data'!$O$4:$O$2342,J$4,'Grid Data'!$M$4:$M$2342,$D$2)*100, 0) -> 0 | K15: =IF( K78>$E$2, SUMIFS(IF($G$2="CPR",'Grid Data'!$V$4:$V$2342,'Grid Data'!$W$4:$W$2342),'Grid Data'!$N$4:$N$2342,$D15,'Grid Data'!$O$4:$O$2342,K$4,'Grid Data'!$M$4:$M$2342,$D$2)*100, 0) -> 2.3807 | L15: =IF( L78>$E$2, SUMIFS(IF($G$2="CPR",'Grid Data'!$V$4:$V$2342,'Grid Data'!$W$4:$W$2342),'Grid Data'!$N$4:$N$2342,$D15,'Grid Data'!$O$4:$O$2342,L$4,'Grid Data'!$M$4:$M$2342,$D$2)*100, 0) -> 1.299 | ... AH15: =IF( AH78>$E$2, SUMIFS(IF($G$2="CPR",'Grid Data'!$V$4:$V$2342,'Grid Data'!$W$4:$W$2342),'Grid Data'!$N$4:$N$2342,$D15,'Grid Data'!$O$4:$O$2342,AH$4,'Grid Data'!$M$4:$M$2342,$D$2)*100, 0) -> 0
D16: 4750 | E16: =IF( E79>$E$2, SUMIFS(IF($G$2="CPR",'Grid Data'!$V$4:$V$2342,'Grid Data'!$W$4:$W$2342),'Grid Data'!$N$4:$N$2342,$D16,'Grid Data'!$O$4:$O$2342,E$4,'Grid Data'!$M$4:$M$2342,$D$2)*100, 0) -> 0.3498 | F16: =IF( F79>$E$2, SUMIFS(IF($G$2="CPR",'Grid Data'!$V$4:$V$2342,'Grid Data'!$W$4:$W$2342),'Grid Data'!$N$4:$N$2342,$D16,'Grid Data'!$O$4:$O$2342,F$4,'Grid Data'!$M$4:$M$2342,$D$2)*100, 0) -> 1.718 | G16: =IF( G79>$E$2, SUMIFS(IF($G$2="CPR",'Grid Data'!$V$4:$V$2342,'Grid Data'!$W$4:$W$2342),'Grid Data'!$N$4:$N$2342,$D16,'Grid Data'!$O$4:$O$2342,G$4,'Grid Data'!$M$4:$M$2342,$D$2)*100, 0) -> 1.0669 | H16: =IF( H79>$E$2, SUMIFS(IF($G$2="CPR",'Grid Data'!$V$4:$V$2342,'Grid Data'!$W$4:$W$2342),'Grid Data'!$N$4:$N$2342,$D16,'Grid Data'!$O$4:$O$2342,H$4,'Grid Data'!$M$4:$M$2342,$D$2)*100, 0) -> 0 | I16: =IF( I79>$E$2, SUMIFS(IF($G$2="CPR",'Grid Data'!$V$4:$V$2342,'Grid Data'!$W$4:$W$2342),'Grid Data'!$N$4:$N$2342,$D16,'Grid Data'!$O$4:$O$2342,I$4,'Grid Data'!$M$4:$M$2342,$D$2)*100, 0) -> 0 | J16: =IF( J79>$E$2, SUMIFS(IF($G$2="CPR",'Grid Data'!$V$4:$V$2342,'Grid Data'!$W$4:$W$2342),'Grid Data'!$N$4:$N$2342,$D16,'Grid Data'!$O$4:$O$2342,J$4,'Grid Data'!$M$4:$M$2342,$D$2)*100, 0) -> 0.8078 | K16: =IF( K79>$E$2, SUMIFS(IF($G$2="CPR",'Grid Data'!$V$4:$V$2342,'Grid Data'!$W$4:$W$2342),'Grid Data'!$N$4:$N$2342,$D16,'Grid Data'!$O$4:$O$2342,K$4,'Grid Data'!$M$4:$M$2342,$D$2)*100, 0) -> 0 | L16: =IF( L79>$E$2, SUMIFS(IF($G$2="CPR",'Grid Data'!$V$4:$V$2342,'Grid Data'!$W$4:$W$2342),'Grid Data'!$N$4:$N$2342,$D16,'Grid Data'!$O$4:$O$2342,L$4,'Grid Data'!$M$4:$M$2342,$D$2)*100, 0) -> 1.9952 | ... AH16: =IF( AH79>$E$2, SUMIFS(IF($G$2="CPR",'Grid Data'!$V$4:$V$2342,'Grid Data'!$W$4:$W$2342),'Grid Data'!$N$4:$N$2342,$D16,'Grid Data'!$O$4:$O$2342,AH$4,'Grid Data'!$M$4:$M$2342,$D$2)*100, 0) -> 0
... D33: 20000 | E33: =IF( E96>$E$2, SUMIFS(IF($G$2="CPR",'Grid Data'!$V$4:$V$2342,'Grid Data'!$W$4:$W$2342),'Grid Data'!$N$4:$N$2342,$D33,'Grid Data'!$O$4:$O$2342,E$4,'Grid Data'!$M$4:$M$2342,$D$2)*100, 0) -> 0 | F33: =IF( F96>$E$2, SUMIFS(IF($G$2="CPR",'Grid Data'!$V$4:$V$2342,'Grid Data'!$W$4:$W$2342),'Grid Data'!$N$4:$N$2342,$D33,'Grid Data'!$O$4:$O$2342,F$4,'Grid Data'!$M$4:$M$2342,$D$2)*100, 0) -> 0 | G33: =IF( G96>$E$2, SUMIFS(IF($G$2="CPR",'Grid Data'!$V$4:$V$2342,'Grid Data'!$W$4:$W$2342),'Grid Data'!$N$4:$N$2342,$D33,'Grid Data'!$O$4:$O$2342,G$4,'Grid Data'!$M$4:$M$2342,$D$2)*100, 0) -> 0 | H33: =IF( H96>$E$2, SUMIFS(IF($G$2="CPR",'Grid Data'!$V$4:$V$2342,'Grid Data'!$W$4:$W$2342),'Grid Data'!$N$4:$N$2342,$D33,'Grid Data'!$O$4:$O$2342,H$4,'Grid Data'!$M$4:$M$2342,$D$2)*100, 0) -> 0 | I33: =IF( I96>$E$2, SUMIFS(IF($G$2="CPR",'Grid Data'!$V$4:$V$2342,'Grid Data'!$W$4:$W$2342),'Grid Data'!$N$4:$N$2342,$D33,'Grid Data'!$O$4:$O$2342,I$4,'Grid Data'!$M$4:$M$2342,$D$2)*100, 0) -> 0 | J33: =IF( J96>$E$2, SUMIFS(IF($G$2="CPR",'Grid Data'!$V$4:$V$2342,'Grid Data'!$W$4:$W$2342),'Grid Data'!$N$4:$N$2342,$D33,'Grid Data'!$O$4:$O$2342,J$4,'Grid Data'!$M$4:$M$2342,$D$2)*100, 0) -> 0 | K33: =IF( K96>$E$2, SUMIFS(IF($G$2="CPR",'Grid Data'!$V$4:$V$2342,'Grid Data'!$W$4:$W$2342),'Grid Data'!$N$4:$N$2342,$D33,'Grid Data'!$O$4:$O$2342,K$4,'Grid Data'!$M$4:$M$2342,$D$2)*100, 0) -> 0 | L33: =IF( L96>$E$2, SUMIFS(IF($G$2="CPR",'Grid Data'!$V$4:$V$2342,'Grid Data'!$W$4:$W$2342),'Grid Data'!$N$4:$N$2342,$D33,'Grid Data'!$O$4:$O$2342,L$4,'Grid Data'!$M$4:$M$2342,$D$2)*100, 0) -> 0 | ... AH33: =IF( AH96>$E$2, SUMIFS(IF($G$2="CPR",'Grid Data'!$V$4:$V$2342,'Grid Data'!$W$4:$W$2342),'Grid Data'!$N$4:$N$2342,$D33,'Grid Data'!$O$4:$O$2342,AH$4,'Grid Data'!$M$4:$M$2342,$D$2)*100, 0) -> 0
E35: Red Means Faster
D36: Change | E36: 5 | F36: 6 | G36: 7 | H36: 8 | I36: 9 | J36: 10 | K36: 12 | L36: 14 | M36: 16 | N36: 18 | O36: 20 | P36: 24 | Q36: 30 | R36: 36 | S36: 42 | T36: 48 | U36: 54 | V36: 60 | W36: 72 | X36: 84 | Y36: 96 | Z36: 108 | AA36: 120 | AB36: 144 | AC36: 168 | AD36: 192 | AE36: 216 | AF36: 240 | AG36: 320 | AH36: 360
D37: 2000 | E37: =IF( E68>$E$2, SUMIFS(IF($G$2="CPR",'Grid Data'!$AH$4:$AH$2342,'Grid Data'!$AI$4:$AI$2342),'Grid Data'!$Z$4:$Z$2342,$D37,'Grid Data'!$AA$4:$AA$2342,E$4,'Grid Data'!$Y$4:$Y$2342,$D$2)*100-E5, "--") -> -- | F37: =IF( F68>$E$2, SUMIFS(IF($G$2="CPR",'Grid Data'!$AH$4:$AH$2342,'Grid Data'!$AI$4:$AI$2342),'Grid Data'!$Z$4:$Z$2342,$D37,'Grid Data'!$AA$4:$AA$2342,F$4,'Grid Data'!$Y$4:$Y$2342,$D$2)*100-F5, "--") -> -- | G37: =IF( G68>$E$2, SUMIFS(IF($G$2="CPR",'Grid Data'!$AH$4:$AH$2342,'Grid Data'!$AI$4:$AI$2342),'Grid Data'!$Z$4:$Z$2342,$D37,'Grid Data'!$AA$4:$AA$2342,G$4,'Grid Data'!$Y$4:$Y$2342,$D$2)*100-G5, "--") -> -- | H37: =IF( H68>$E$2, SUMIFS(IF($G$2="CPR",'Grid Data'!$AH$4:$AH$2342,'Grid Data'!$AI$4:$AI$2342),'Grid Data'!$Z$4:$Z$2342,$D37,'Grid Data'!$AA$4:$AA$2342,H$4,'Grid Data'!$Y$4:$Y$2342,$D$2)*100-H5, "--") -> -- | I37: =IF( I68>$E$2, SUMIFS(IF($G$2="CPR",'Grid Data'!$AH$4:$AH$2342,'Grid Data'!$AI$4:$AI$2342),'Grid Data'!$Z$4:$Z$2342,$D37,'Grid Data'!$AA$4:$AA$2342,I$4,'Grid Data'!$Y$4:$Y$2342,$D$2)*100-I5, "--") -> -- | J37: =IF( J68>$E$2, SUMIFS(IF($G$2="CPR",'Grid Data'!$AH$4:$AH$2342,'Grid Data'!$AI$4:$AI$2342),'Grid Data'!$Z$4:$Z$2342,$D37,'Grid Data'!$AA$4:$AA$2342,J$4,'Grid Data'!$Y$4:$Y$2342,$D$2)*100-J5, "--") -> -- | K37: =IF( K68>$E$2, SUMIFS(IF($G$2="CPR",'Grid Data'!$AH$4:$AH$2342,'Grid Data'!$AI$4:$AI$2342),'Grid Data'!$Z$4:$Z$2342,$D37,'Grid Data'!$AA$4:$AA$2342,K$4,'Grid Data'!$Y$4:$Y$2342,$D$2)*100-K5, "--") -> -- | L37: =IF( L68>$E$2, SUMIFS(IF($G$2="CPR",'Grid Data'!$AH$4:$AH$2342,'Grid Data'!$AI$4:$AI$2342),'Grid Data'!$Z$4:$Z$2342,$D37,'Grid Data'!$AA$4:$AA$2342,L$4,'Grid Data'!$Y$4:$Y$2342,$D$2)*100-L5, "--") -> -- | ... AH37: =IF( AH68>$E$2, SUMIFS(IF($G$2="CPR",'Grid Data'!$AH$4:$AH$2342,'Grid Data'!$AI$4:$AI$2342),'Grid Data'!$Z$4:$Z$2342,$D37,'Grid Data'!$AA$4:$AA$2342,AH$4,'Grid Data'!$Y$4:$Y$2342,$D$2)*100-AH5, "--") -> --
A38: =SUMPRODUCT(T37:W46,T68:W77)/SUM(T68:W77) -> -0.029477432 | D38: 2250 | E38: =IF( E69>$E$2, SUMIFS(IF($G$2="CPR",'Grid Data'!$AH$4:$AH$2342,'Grid Data'!$AI$4:$AI$2342),'Grid Data'!$Z$4:$Z$2342,$D38,'Grid Data'!$AA$4:$AA$2342,E$4,'Grid Data'!$Y$4:$Y$2342,$D$2)*100-E6, "--") -> -- | F38: =IF( F69>$E$2, SUMIFS(IF($G$2="CPR",'Grid Data'!$AH$4:$AH$2342,'Grid Data'!$AI$4:$AI$2342),'Grid Data'!$Z$4:$Z$2342,$D38,'Grid Data'!$AA$4:$AA$2342,F$4,'Grid Data'!$Y$4:$Y$2342,$D$2)*100-F6, "--") -> -- | G38: =IF( G69>$E$2, SUMIFS(IF($G$2="CPR",'Grid Data'!$AH$4:$AH$2342,'Grid Data'!$AI$4:$AI$2342),'Grid Data'!$Z$4:$Z$2342,$D38,'Grid Data'!$AA$4:$AA$2342,G$4,'Grid Data'!$Y$4:$Y$2342,$D$2)*100-G6, "--") -> -- | H38: =IF( H69>$E$2, SUMIFS(IF($G$2="CPR",'Grid Data'!$AH$4:$AH$2342,'Grid Data'!$AI$4:$AI$2342),'Grid Data'!$Z$4:$Z$2342,$D38,'Grid Data'!$AA$4:$AA$2342,H$4,'Grid Data'!$Y$4:$Y$2342,$D$2)*100-H6, "--") -> -- | I38: =IF( I69>$E$2, SUMIFS(IF($G$2="CPR",'Grid Data'!$AH$4:$AH$2342,'Grid Data'!$AI$4:$AI$2342),'Grid Data'!$Z$4:$Z$2342,$D38,'Grid Data'!$AA$4:$AA$2342,I$4,'Grid Data'!$Y$4:$Y$2342,$D$2)*100-I6, "--") -> -- | J38: =IF( J69>$E$2, SUMIFS(IF($G$2="CPR",'Grid Data'!$AH$4:$AH$2342,'Grid Data'!$AI$4:$AI$2342),'Grid Data'!$Z$4:$Z$2342,$D38,'Grid Data'!$AA$4:$AA$2342,J$4,'Grid Data'!$Y$4:$Y$2342,$D$2)*100-J6, "--") -> -- | K38: =IF( K69>$E$2, SUMIFS(IF($G$2="CPR",'Grid Data'!$AH$4:$AH$2342,'Grid Data'!$AI$4:$AI$2342),'Grid Data'!$Z$4:$Z$2342,$D38,'Grid Data'!$AA$4:$AA$2342,K$4,'Grid Data'!$Y$4:$Y$2342,$D$2)*100-K6, "--") -> -- | L38: =IF( L69>$E$2, SUMIFS(IF($G$2="CPR",'Grid Data'!$AH$4:$AH$2342,'Grid Data'!$AI$4:$AI$2342),'Grid Data'!$Z$4:$Z$2342,$D38,'Grid Data'!$AA$4:$AA$2342,L$4,'Grid Data'!$Y$4:$Y$2342,$D$2)*100-L6, "--") -> -- | ... AH38: =IF( AH69>$E$2, SUMIFS(IF($G$2="CPR",'Grid Data'!$AH$4:$AH$2342,'Grid Data'!$AI$4:$AI$2342),'Grid Data'!$Z$4:$Z$2342,$D38,'Grid Data'!$AA$4:$AA$2342,AH$4,'Grid Data'!$Y$4:$Y$2342,$D$2)*100-AH6, "--") -> --
D39: 2500 | E39: =IF( E70>$E$2, SUMIFS(IF($G$2="CPR",'Grid Data'!$AH$4:$AH$2342,'Grid Data'!$AI$4:$AI$2342),'Grid Data'!$Z$4:$Z$2342,$D39,'Grid Data'!$AA$4:$AA$2342,E$4,'Grid Data'!$Y$4:$Y$2342,$D$2)*100-E7, "--") -> -- | F39: =IF( F70>$E$2, SUMIFS(IF($G$2="CPR",'Grid Data'!$AH$4:$AH$2342,'Grid Data'!$AI$4:$AI$2342),'Grid Data'!$Z$4:$Z$2342,$D39,'Grid Data'!$AA$4:$AA$2342,F$4,'Grid Data'!$Y$4:$Y$2342,$D$2)*100-F7, "--") -> -- | G39: =IF( G70>$E$2, SUMIFS(IF($G$2="CPR",'Grid Data'!$AH$4:$AH$2342,'Grid Data'!$AI$4:$AI$2342),'Grid Data'!$Z$4:$Z$2342,$D39,'Grid Data'!$AA$4:$AA$2342,G$4,'Grid Data'!$Y$4:$Y$2342,$D$2)*100-G7, "--") -> -- | H39: =IF( H70>$E$2, SUMIFS(IF($G$2="CPR",'Grid Data'!$AH$4:$AH$2342,'Grid Data'!$AI$4:$AI$2342),'Grid Data'!$Z$4:$Z$2342,$D39,'Grid Data'!$AA$4:$AA$2342,H$4,'Grid Data'!$Y$4:$Y$2342,$D$2)*100-H7, "--") -> -- | I39: =IF( I70>$E$2, SUMIFS(IF($G$2="CPR",'Grid Data'!$AH$4:$AH$2342,'Grid Data'!$AI$4:$AI$2342),'Grid Data'!$Z$4:$Z$2342,$D39,'Grid Data'!$AA$4:$AA$2342,I$4,'Grid Data'!$Y$4:$Y$2342,$D$2)*100-I7, "--") -> -- | J39: =IF( J70>$E$2, SUMIFS(IF($G$2="CPR",'Grid Data'!$AH$4:$AH$2342,'Grid Data'!$AI$4:$AI$2342),'Grid Data'!$Z$4:$Z$2342,$D39,'Grid Data'!$AA$4:$AA$2342,J$4,'Grid Data'!$Y$4:$Y$2342,$D$2)*100-J7, "--") -> -- | K39: =IF( K70>$E$2, SUMIFS(IF($G$2="CPR",'Grid Data'!$AH$4:$AH$2342,'Grid Data'!$AI$4:$AI$2342),'Grid Data'!$Z$4:$Z$2342,$D39,'Grid Data'!$AA$4:$AA$2342,K$4,'Grid Data'!$Y$4:$Y$2342,$D$2)*100-K7, "--") -> -- | L39: =IF( L70>$E$2, SUMIFS(IF($G$2="CPR",'Grid Data'!$AH$4:$AH$2342,'Grid Data'!$AI$4:$AI$2342),'Grid Data'!$Z$4:$Z$2342,$D39,'Grid Data'!$AA$4:$AA$2342,L$4,'Grid Data'!$Y$4:$Y$2342,$D$2)*100-L7, "--") -> -- | ... AH39: =IF( AH70>$E$2, SUMIFS(IF($G$2="CPR",'Grid Data'!$AH$4:$AH$2342,'Grid Data'!$AI$4:$AI$2342),'Grid Data'!$Z$4:$Z$2342,$D39,'Grid Data'!$AA$4:$AA$2342,AH$4,'Grid Data'!$Y$4:$Y$2342,$D$2)*100-AH7, "--") -> --
D40: 2750 | E40: =IF( E71>$E$2, SUMIFS(IF($G$2="CPR",'Grid Data'!$AH$4:$AH$2342,'Grid Data'!$AI$4:$AI$2342),'Grid Data'!$Z$4:$Z$2342,$D40,'Grid Data'!$AA$4:$AA$2342,E$4,'Grid Data'!$Y$4:$Y$2342,$D$2)*100-E8, "--") -> -- | F40: =IF( F71>$E$2, SUMIFS(IF($G$2="CPR",'Grid Data'!$AH$4:$AH$2342,'Grid Data'!$AI$4:$AI$2342),'Grid Data'!$Z$4:$Z$2342,$D40,'Grid Data'!$AA$4:$AA$2342,F$4,'Grid Data'!$Y$4:$Y$2342,$D$2)*100-F8, "--") -> -- | G40: =IF( G71>$E$2, SUMIFS(IF($G$2="CPR",'Grid Data'!$AH$4:$AH$2342,'Grid Data'!$AI$4:$AI$2342),'Grid Data'!$Z$4:$Z$2342,$D40,'Grid Data'!$AA$4:$AA$2342,G$4,'Grid Data'!$Y$4:$Y$2342,$D$2)*100-G8, "--") -> -- | H40: =IF( H71>$E$2, SUMIFS(IF($G$2="CPR",'Grid Data'!$AH$4:$AH$2342,'Grid Data'!$AI$4:$AI$2342),'Grid Data'!$Z$4:$Z$2342,$D40,'Grid Data'!$AA$4:$AA$2342,H$4,'Grid Data'!$Y$4:$Y$2342,$D$2)*100-H8, "--") -> -- | I40: =IF( I71>$E$2, SUMIFS(IF($G$2="CPR",'Grid Data'!$AH$4:$AH$2342,'Grid Data'!$AI$4:$AI$2342),'Grid Data'!$Z$4:$Z$2342,$D40,'Grid Data'!$AA$4:$AA$2342,I$4,'Grid Data'!$Y$4:$Y$2342,$D$2)*100-I8, "--") -> -- | J40: =IF( J71>$E$2, SUMIFS(IF($G$2="CPR",'Grid Data'!$AH$4:$AH$2342,'Grid Data'!$AI$4:$AI$2342),'Grid Data'!$Z$4:$Z$2342,$D40,'Grid Data'!$AA$4:$AA$2342,J$4,'Grid Data'!$Y$4:$Y$2342,$D$2)*100-J8, "--") -> -- | K40: =IF( K71>$E$2, SUMIFS(IF($G$2="CPR",'Grid Data'!$AH$4:$AH$2342,'Grid Data'!$AI$4:$AI$2342),'Grid Data'!$Z$4:$Z$2342,$D40,'Grid Data'!$AA$4:$AA$2342,K$4,'Grid Data'!$Y$4:$Y$2342,$D$2)*100-K8, "--") -> -- | L40: =IF( L71>$E$2, SUMIFS(IF($G$2="CPR",'Grid Data'!$AH$4:$AH$2342,'Grid Data'!$AI$4:$AI$2342),'Grid Data'!$Z$4:$Z$2342,$D40,'Grid Data'!$AA$4:$AA$2342,L$4,'Grid Data'!$Y$4:$Y$2342,$D$2)*100-L8, "--") -> -- | ... AH40: =IF( AH71>$E$2, SUMIFS(IF($G$2="CPR",'Grid Data'!$AH$4:$AH$2342,'Grid Data'!$AI$4:$AI$2342),'Grid Data'!$Z$4:$Z$2342,$D40,'Grid Data'!$AA$4:$AA$2342,AH$4,'Grid Data'!$Y$4:$Y$2342,$D$2)*100-AH8, "--") -> --
D41: 3000 | E41: =IF( E72>$E$2, SUMIFS(IF($G$2="CPR",'Grid Data'!$AH$4:$AH$2342,'Grid Data'!$AI$4:$AI$2342),'Grid Data'!$Z$4:$Z$2342,$D41,'Grid Data'!$AA$4:$AA$2342,E$4,'Grid Data'!$Y$4:$Y$2342,$D$2)*100-E9, "--") -> -- | F41: =IF( F72>$E$2, SUMIFS(IF($G$2="CPR",'Grid Data'!$AH$4:$AH$2342,'Grid Data'!$AI$4:$AI$2342),'Grid Data'!$Z$4:$Z$2342,$D41,'Grid Data'!$AA$4:$AA$2342,F$4,'Grid Data'!$Y$4:$Y$2342,$D$2)*100-F9, "--") -> -- | G41: =IF( G72>$E$2, SUMIFS(IF($G$2="CPR",'Grid Data'!$AH$4:$AH$2342,'Grid Data'!$AI$4:$AI$2342),'Grid Data'!$Z$4:$Z$2342,$D41,'Grid Data'!$AA$4:$AA$2342,G$4,'Grid Data'!$Y$4:$Y$2342,$D$2)*100-G9, "--") -> -- | H41: =IF( H72>$E$2, SUMIFS(IF($G$2="CPR",'Grid Data'!$AH$4:$AH$2342,'Grid Data'!$AI$4:$AI$2342),'Grid Data'!$Z$4:$Z$2342,$D41,'Grid Data'!$AA$4:$AA$2342,H$4,'Grid Data'!$Y$4:$Y$2342,$D$2)*100-H9, "--") -> -- | I41: =IF( I72>$E$2, SUMIFS(IF($G$2="CPR",'Grid Data'!$AH$4:$AH$2342,'Grid Data'!$AI$4:$AI$2342),'Grid Data'!$Z$4:$Z$2342,$D41,'Grid Data'!$AA$4:$AA$2342,I$4,'Grid Data'!$Y$4:$Y$2342,$D$2)*100-I9, "--") -> -- | J41: =IF( J72>$E$2, SUMIFS(IF($G$2="CPR",'Grid Data'!$AH$4:$AH$2342,'Grid Data'!$AI$4:$AI$2342),'Grid Data'!$Z$4:$Z$2342,$D41,'Grid Data'!$AA$4:$AA$2342,J$4,'Grid Data'!$Y$4:$Y$2342,$D$2)*100-J9, "--") -> -- | K41: =IF( K72>$E$2, SUMIFS(IF($G$2="CPR",'Grid Data'!$AH$4:$AH$2342,'Grid Data'!$AI$4:$AI$2342),'Grid Data'!$Z$4:$Z$2342,$D41,'Grid Data'!$AA$4:$AA$2342,K$4,'Grid Data'!$Y$4:$Y$2342,$D$2)*100-K9, "--") -> -- | L41: =IF( L72>$E$2, SUMIFS(IF($G$2="CPR",'Grid Data'!$AH$4:$AH$2342,'Grid Data'!$AI$4:$AI$2342),'Grid Data'!$Z$4:$Z$2342,$D41,'Grid Data'!$AA$4:$AA$2342,L$4,'Grid Data'!$Y$4:$Y$2342,$D$2)*100-L9, "--") -> -- | ... AH41: =IF( AH72>$E$2, SUMIFS(IF($G$2="CPR",'Grid Data'!$AH$4:$AH$2342,'Grid Data'!$AI$4:$AI$2342),'Grid Data'!$Z$4:$Z$2342,$D41,'Grid Data'!$AA$4:$AA$2342,AH$4,'Grid Data'!$Y$4:$Y$2342,$D$2)*100-AH9, "--") -> --
D42: 3250 | E42: =IF( E73>$E$2, SUMIFS(IF($G$2="CPR",'Grid Data'!$AH$4:$AH$2342,'Grid Data'!$AI$4:$AI$2342),'Grid Data'!$Z$4:$Z$2342,$D42,'Grid Data'!$AA$4:$AA$2342,E$4,'Grid Data'!$Y$4:$Y$2342,$D$2)*100-E10, "--") -> 0 | F42: =IF( F73>$E$2, SUMIFS(IF($G$2="CPR",'Grid Data'!$AH$4:$AH$2342,'Grid Data'!$AI$4:$AI$2342),'Grid Data'!$Z$4:$Z$2342,$D42,'Grid Data'!$AA$4:$AA$2342,F$4,'Grid Data'!$Y$4:$Y$2342,$D$2)*100-F10, "--") -> -- | G42: =IF( G73>$E$2, SUMIFS(IF($G$2="CPR",'Grid Data'!$AH$4:$AH$2342,'Grid Data'!$AI$4:$AI$2342),'Grid Data'!$Z$4:$Z$2342,$D42,'Grid Data'!$AA$4:$AA$2342,G$4,'Grid Data'!$Y$4:$Y$2342,$D$2)*100-G10, "--") -> -- | H42: =IF( H73>$E$2, SUMIFS(IF($G$2="CPR",'Grid Data'!$AH$4:$AH$2342,'Grid Data'!$AI$4:$AI$2342),'Grid Data'!$Z$4:$Z$2342,$D42,'Grid Data'!$AA$4:$AA$2342,H$4,'Grid Data'!$Y$4:$Y$2342,$D$2)*100-H10, "--") -> -- | I42: =IF( I73>$E$2, SUMIFS(IF($G$2="CPR",'Grid Data'!$AH$4:$AH$2342,'Grid Data'!$AI$4:$AI$2342),'Grid Data'!$Z$4:$Z$2342,$D42,'Grid Data'!$AA$4:$AA$2342,I$4,'Grid Data'!$Y$4:$Y$2342,$D$2)*100-I10, "--") -> -- | J42: =IF( J73>$E$2, SUMIFS(IF($G$2="CPR",'Grid Data'!$AH$4:$AH$2342,'Grid Data'!$AI$4:$AI$2342),'Grid Data'!$Z$4:$Z$2342,$D42,'Grid Data'!$AA$4:$AA$2342,J$4,'Grid Data'!$Y$4:$Y$2342,$D$2)*100-J10, "--") -> -- | K42: =IF( K73>$E$2, SUMIFS(IF($G$2="CPR",'Grid Data'!$AH$4:$AH$2342,'Grid Data'!$AI$4:$AI$2342),'Grid Data'!$Z$4:$Z$2342,$D42,'Grid Data'!$AA$4:$AA$2342,K$4,'Grid Data'!$Y$4:$Y$2342,$D$2)*100-K10, "--") -> -- | L42: =IF( L73>$E$2, SUMIFS(IF($G$2="CPR",'Grid Data'!$AH$4:$AH$2342,'Grid Data'!$AI$4:$AI$2342),'Grid Data'!$Z$4:$Z$2342,$D42,'Grid Data'!$AA$4:$AA$2342,L$4,'Grid Data'!$Y$4:$Y$2342,$D$2)*100-L10, "--") -> -- | ... AH42: =IF( AH73>$E$2, SUMIFS(IF($G$2="CPR",'Grid Data'!$AH$4:$AH$2342,'Grid Data'!$AI$4:$AI$2342),'Grid Data'!$Z$4:$Z$2342,$D42,'Grid Data'!$AA$4:$AA$2342,AH$4,'Grid Data'!$Y$4:$Y$2342,$D$2)*100-AH10, "--") -> --
D43: 3500 | E43: =IF( E74>$E$2, SUMIFS(IF($G$2="CPR",'Grid Data'!$AH$4:$AH$2342,'Grid Data'!$AI$4:$AI$2342),'Grid Data'!$Z$4:$Z$2342,$D43,'Grid Data'!$AA$4:$AA$2342,E$4,'Grid Data'!$Y$4:$Y$2342,$D$2)*100-E11, "--") -> 0 | F43: =IF( F74>$E$2, SUMIFS(IF($G$2="CPR",'Grid Data'!$AH$4:$AH$2342,'Grid Data'!$AI$4:$AI$2342),'Grid Data'!$Z$4:$Z$2342,$D43,'Grid Data'!$AA$4:$AA$2342,F$4,'Grid Data'!$Y$4:$Y$2342,$D$2)*100-F11, "--") -> -- | G43: =IF( G74>$E$2, SUMIFS(IF($G$2="CPR",'Grid Data'!$AH$4:$AH$2342,'Grid Data'!$AI$4:$AI$2342),'Grid Data'!$Z$4:$Z$2342,$D43,'Grid Data'!$AA$4:$AA$2342,G$4,'Grid Data'!$Y$4:$Y$2342,$D$2)*100-G11, "--") -> -- | H43: =IF( H74>$E$2, SUMIFS(IF($G$2="CPR",'Grid Data'!$AH$4:$AH$2342,'Grid Data'!$AI$4:$AI$2342),'Grid Data'!$Z$4:$Z$2342,$D43,'Grid Data'!$AA$4:$AA$2342,H$4,'Grid Data'!$Y$4:$Y$2342,$D$2)*100-H11, "--") -> -- | I43: =IF( I74>$E$2, SUMIFS(IF($G$2="CPR",'Grid Data'!$AH$4:$AH$2342,'Grid Data'!$AI$4:$AI$2342),'Grid Data'!$Z$4:$Z$2342,$D43,'Grid Data'!$AA$4:$AA$2342,I$4,'Grid Data'!$Y$4:$Y$2342,$D$2)*100-I11, "--") -> -- | J43: =IF( J74>$E$2, SUMIFS(IF($G$2="CPR",'Grid Data'!$AH$4:$AH$2342,'Grid Data'!$AI$4:$AI$2342),'Grid Data'!$Z$4:$Z$2342,$D43,'Grid Data'!$AA$4:$AA$2342,J$4,'Grid Data'!$Y$4:$Y$2342,$D$2)*100-J11, "--") -> -- | K43: =IF( K74>$E$2, SUMIFS(IF($G$2="CPR",'Grid Data'!$AH$4:$AH$2342,'Grid Data'!$AI$4:$AI$2342),'Grid Data'!$Z$4:$Z$2342,$D43,'Grid Data'!$AA$4:$AA$2342,K$4,'Grid Data'!$Y$4:$Y$2342,$D$2)*100-K11, "--") -> -- | L43: =IF( L74>$E$2, SUMIFS(IF($G$2="CPR",'Grid Data'!$AH$4:$AH$2342,'Grid Data'!$AI$4:$AI$2342),'Grid Data'!$Z$4:$Z$2342,$D43,'Grid Data'!$AA$4:$AA$2342,L$4,'Grid Data'!$Y$4:$Y$2342,$D$2)*100-L11, "--") -> -- | ... AH43: =IF( AH74>$E$2, SUMIFS(IF($G$2="CPR",'Grid Data'!$AH$4:$AH$2342,'Grid Data'!$AI$4:$AI$2342),'Grid Data'!$Z$4:$Z$2342,$D43,'Grid Data'!$AA$4:$AA$2342,AH$4,'Grid Data'!$Y$4:$Y$2342,$D$2)*100-AH11, "--") -> --
D44: 3750 | E44: =IF( E75>$E$2, SUMIFS(IF($G$2="CPR",'Grid Data'!$AH$4:$AH$2342,'Grid Data'!$AI$4:$AI$2342),'Grid Data'!$Z$4:$Z$2342,$D44,'Grid Data'!$AA$4:$AA$2342,E$4,'Grid Data'!$Y$4:$Y$2342,$D$2)*100-E12, "--") -> 0 | F44: =IF( F75>$E$2, SUMIFS(IF($G$2="CPR",'Grid Data'!$AH$4:$AH$2342,'Grid Data'!$AI$4:$AI$2342),'Grid Data'!$Z$4:$Z$2342,$D44,'Grid Data'!$AA$4:$AA$2342,F$4,'Grid Data'!$Y$4:$Y$2342,$D$2)*100-F12, "--") -> 0 | G44: =IF( G75>$E$2, SUMIFS(IF($G$2="CPR",'Grid Data'!$AH$4:$AH$2342,'Grid Data'!$AI$4:$AI$2342),'Grid Data'!$Z$4:$Z$2342,$D44,'Grid Data'!$AA$4:$AA$2342,G$4,'Grid Data'!$Y$4:$Y$2342,$D$2)*100-G12, "--") -> 0 | H44: =IF( H75>$E$2, SUMIFS(IF($G$2="CPR",'Grid Data'!$AH$4:$AH$2342,'Grid Data'!$AI$4:$AI$2342),'Grid Data'!$Z$4:$Z$2342,$D44,'Grid Data'!$AA$4:$AA$2342,H$4,'Grid Data'!$Y$4:$Y$2342,$D$2)*100-H12, "--") -> 0 | I44: =IF( I75>$E$2, SUMIFS(IF($G$2="CPR",'Grid Data'!$AH$4:$AH$2342,'Grid Data'!$AI$4:$AI$2342),'Grid Data'!$Z$4:$Z$2342,$D44,'Grid Data'!$AA$4:$AA$2342,I$4,'Grid Data'!$Y$4:$Y$2342,$D$2)*100-I12, "--") -> -- | J44: =IF( J75>$E$2, SUMIFS(IF($G$2="CPR",'Grid Data'!$AH$4:$AH$2342,'Grid Data'!$AI$4:$AI$2342),'Grid Data'!$Z$4:$Z$2342,$D44,'Grid Data'!$AA$4:$AA$2342,J$4,'Grid Data'!$Y$4:$Y$2342,$D$2)*100-J12, "--") -> 0 | K44: =IF( K75>$E$2, SUMIFS(IF($G$2="CPR",'Grid Data'!$AH$4:$AH$2342,'Grid Data'!$AI$4:$AI$2342),'Grid Data'!$Z$4:$Z$2342,$D44,'Grid Data'!$AA$4:$AA$2342,K$4,'Grid Data'!$Y$4:$Y$2342,$D$2)*100-K12, "--") -> 0 | L44: =IF( L75>$E$2, SUMIFS(IF($G$2="CPR",'Grid Data'!$AH$4:$AH$2342,'Grid Data'!$AI$4:$AI$2342),'Grid Data'!$Z$4:$Z$2342,$D44,'Grid Data'!$AA$4:$AA$2342,L$4,'Grid Data'!$Y$4:$Y$2342,$D$2)*100-L12, "--") -> 0 | ... AH44: =IF( AH75>$E$2, SUMIFS(IF($G$2="CPR",'Grid Data'!$AH$4:$AH$2342,'Grid Data'!$AI$4:$AI$2342),'Grid Data'!$Z$4:$Z$2342,$D44,'Grid Data'!$AA$4:$AA$2342,AH$4,'Grid Data'!$Y$4:$Y$2342,$D$2)*100-AH12, "--") -> --
D45: 4000 | E45: =IF( E76>$E$2, SUMIFS(IF($G$2="CPR",'Grid Data'!$AH$4:$AH$2342,'Grid Data'!$AI$4:$AI$2342),'Grid Data'!$Z$4:$Z$2342,$D45,'Grid Data'!$AA$4:$AA$2342,E$4,'Grid Data'!$Y$4:$Y$2342,$D$2)*100-E13, "--") -> 0.0453 | F45: =IF( F76>$E$2, SUMIFS(IF($G$2="CPR",'Grid Data'!$AH$4:$AH$2342,'Grid Data'!$AI$4:$AI$2342),'Grid Data'!$Z$4:$Z$2342,$D45,'Grid Data'!$AA$4:$AA$2342,F$4,'Grid Data'!$Y$4:$Y$2342,$D$2)*100-F13, "--") -> 0 | G45: =IF( G76>$E$2, SUMIFS(IF($G$2="CPR",'Grid Data'!$AH$4:$AH$2342,'Grid Data'!$AI$4:$AI$2342),'Grid Data'!$Z$4:$Z$2342,$D45,'Grid Data'!$AA$4:$AA$2342,G$4,'Grid Data'!$Y$4:$Y$2342,$D$2)*100-G13, "--") -> 0 | H45: =IF( H76>$E$2, SUMIFS(IF($G$2="CPR",'Grid Data'!$AH$4:$AH$2342,'Grid Data'!$AI$4:$AI$2342),'Grid Data'!$Z$4:$Z$2342,$D45,'Grid Data'!$AA$4:$AA$2342,H$4,'Grid Data'!$Y$4:$Y$2342,$D$2)*100-H13, "--") -> -0.5643 | I45: =IF( I76>$E$2, SUMIFS(IF($G$2="CPR",'Grid Data'!$AH$4:$AH$2342,'Grid Data'!$AI$4:$AI$2342),'Grid Data'!$Z$4:$Z$2342,$D45,'Grid Data'!$AA$4:$AA$2342,I$4,'Grid Data'!$Y$4:$Y$2342,$D$2)*100-I13, "--") -> -1.2577 | J45: =IF( J76>$E$2, SUMIFS(IF($G$2="CPR",'Grid Data'!$AH$4:$AH$2342,'Grid Data'!$AI$4:$AI$2342),'Grid Data'!$Z$4:$Z$2342,$D45,'Grid Data'!$AA$4:$AA$2342,J$4,'Grid Data'!$Y$4:$Y$2342,$D$2)*100-J13, "--") -> 1.9207 | K45: =IF( K76>$E$2, SUMIFS(IF($G$2="CPR",'Grid Data'!$AH$4:$AH$2342,'Grid Data'!$AI$4:$AI$2342),'Grid Data'!$Z$4:$Z$2342,$D45,'Grid Data'!$AA$4:$AA$2342,K$4,'Grid Data'!$Y$4:$Y$2342,$D$2)*100-K13, "--") -> 2.324 | L45: =IF( L76>$E$2, SUMIFS(IF($G$2="CPR",'Grid Data'!$AH$4:$AH$2342,'Grid Data'!$AI$4:$AI$2342),'Grid Data'!$Z$4:$Z$2342,$D45,'Grid Data'!$AA$4:$AA$2342,L$4,'Grid Data'!$Y$4:$Y$2342,$D$2)*100-L13, "--") -> 0.0039 | ... AH45: =IF( AH76>$E$2, SUMIFS(IF($G$2="CPR",'Grid Data'!$AH$4:$AH$2342,'Grid Data'!$AI$4:$AI$2342),'Grid Data'!$Z$4:$Z$2342,$D45,'Grid Data'!$AA$4:$AA$2342,AH$4,'Grid Data'!$Y$4:$Y$2342,$D$2)*100-AH13, "--") -> --
D46: 4250 | E46: =IF( E77>$E$2, SUMIFS(IF($G$2="CPR",'Grid Data'!$AH$4:$AH$2342,'Grid Data'!$AI$4:$AI$2342),'Grid Data'!$Z$4:$Z$2342,$D46,'Grid Data'!$AA$4:$AA$2342,E$4,'Grid Data'!$Y$4:$Y$2342,$D$2)*100-E14, "--") -> 0.4851 | F46: =IF( F77>$E$2, SUMIFS(IF($G$2="CPR",'Grid Data'!$AH$4:$AH$2342,'Grid Data'!$AI$4:$AI$2342),'Grid Data'!$Z$4:$Z$2342,$D46,'Grid Data'!$AA$4:$AA$2342,F$4,'Grid Data'!$Y$4:$Y$2342,$D$2)*100-F14, "--") -> 0 | G46: =IF( G77>$E$2, SUMIFS(IF($G$2="CPR",'Grid Data'!$AH$4:$AH$2342,'Grid Data'!$AI$4:$AI$2342),'Grid Data'!$Z$4:$Z$2342,$D46,'Grid Data'!$AA$4:$AA$2342,G$4,'Grid Data'!$Y$4:$Y$2342,$D$2)*100-G14, "--") -> 0 | H46: =IF( H77>$E$2, SUMIFS(IF($G$2="CPR",'Grid Data'!$AH$4:$AH$2342,'Grid Data'!$AI$4:$AI$2342),'Grid Data'!$Z$4:$Z$2342,$D46,'Grid Data'!$AA$4:$AA$2342,H$4,'Grid Data'!$Y$4:$Y$2342,$D$2)*100-H14, "--") -> 0 | I46: =IF( I77>$E$2, SUMIFS(IF($G$2="CPR",'Grid Data'!$AH$4:$AH$2342,'Grid Data'!$AI$4:$AI$2342),'Grid Data'!$Z$4:$Z$2342,$D46,'Grid Data'!$AA$4:$AA$2342,I$4,'Grid Data'!$Y$4:$Y$2342,$D$2)*100-I14, "--") -> 0 | J46: =IF( J77>$E$2, SUMIFS(IF($G$2="CPR",'Grid Data'!$AH$4:$AH$2342,'Grid Data'!$AI$4:$AI$2342),'Grid Data'!$Z$4:$Z$2342,$D46,'Grid Data'!$AA$4:$AA$2342,J$4,'Grid Data'!$Y$4:$Y$2342,$D$2)*100-J14, "--") -> 0 | K46: =IF( K77>$E$2, SUMIFS(IF($G$2="CPR",'Grid Data'!$AH$4:$AH$2342,'Grid Data'!$AI$4:$AI$2342),'Grid Data'!$Z$4:$Z$2342,$D46,'Grid Data'!$AA$4:$AA$2342,K$4,'Grid Data'!$Y$4:$Y$2342,$D$2)*100-K14, "--") -> 0 | L46: =IF( L77>$E$2, SUMIFS(IF($G$2="CPR",'Grid Data'!$AH$4:$AH$2342,'Grid Data'!$AI$4:$AI$2342),'Grid Data'!$Z$4:$Z$2342,$D46,'Grid Data'!$AA$4:$AA$2342,L$4,'Grid Data'!$Y$4:$Y$2342,$D$2)*100-L14, "--") -> 0 | ... AH46: =IF( AH77>$E$2, SUMIFS(IF($G$2="CPR",'Grid Data'!$AH$4:$AH$2342,'Grid Data'!$AI$4:$AI$2342),'Grid Data'!$Z$4:$Z$2342,$D46,'Grid Data'!$AA$4:$AA$2342,AH$4,'Grid Data'!$Y$4:$Y$2342,$D$2)*100-AH14, "--") -> --
D47: 4500 | E47: =IF( E78>$E$2, SUMIFS(IF($G$2="CPR",'Grid Data'!$AH$4:$AH$2342,'Grid Data'!$AI$4:$AI$2342),'Grid Data'!$Z$4:$Z$2342,$D47,'Grid Data'!$AA$4:$AA$2342,E$4,'Grid Data'!$Y$4:$Y$2342,$D$2)*100-E15, "--") -> 0 | F47: =IF( F78>$E$2, SUMIFS(IF($G$2="CPR",'Grid Data'!$AH$4:$AH$2342,'Grid Data'!$AI$4:$AI$2342),'Grid Data'!$Z$4:$Z$2342,$D47,'Grid Data'!$AA$4:$AA$2342,F$4,'Grid Data'!$Y$4:$Y$2342,$D$2)*100-F15, "--") -> -1.6929 | G47: =IF( G78>$E$2, SUMIFS(IF($G$2="CPR",'Grid Data'!$AH$4:$AH$2342,'Grid Data'!$AI$4:$AI$2342),'Grid Data'!$Z$4:$Z$2342,$D47,'Grid Data'!$AA$4:$AA$2342,G$4,'Grid Data'!$Y$4:$Y$2342,$D$2)*100-G15, "--") -> 1.9001 | H47: =IF( H78>$E$2, SUMIFS(IF($G$2="CPR",'Grid Data'!$AH$4:$AH$2342,'Grid Data'!$AI$4:$AI$2342),'Grid Data'!$Z$4:$Z$2342,$D47,'Grid Data'!$AA$4:$AA$2342,H$4,'Grid Data'!$Y$4:$Y$2342,$D$2)*100-H15, "--") -> 0 | I47: =IF( I78>$E$2, SUMIFS(IF($G$2="CPR",'Grid Data'!$AH$4:$AH$2342,'Grid Data'!$AI$4:$AI$2342),'Grid Data'!$Z$4:$Z$2342,$D47,'Grid Data'!$AA$4:$AA$2342,I$4,'Grid Data'!$Y$4:$Y$2342,$D$2)*100-I15, "--") -> 0 | J47: =IF( J78>$E$2, SUMIFS(IF($G$2="CPR",'Grid Data'!$AH$4:$AH$2342,'Grid Data'!$AI$4:$AI$2342),'Grid Data'!$Z$4:$Z$2342,$D47,'Grid Data'!$AA$4:$AA$2342,J$4,'Grid Data'!$Y$4:$Y$2342,$D$2)*100-J15, "--") -> 0 | K47: =IF( K78>$E$2, SUMIFS(IF($G$2="CPR",'Grid Data'!$AH$4:$AH$2342,'Grid Data'!$AI$4:$AI$2342),'Grid Data'!$Z$4:$Z$2342,$D47,'Grid Data'!$AA$4:$AA$2342,K$4,'Grid Data'!$Y$4:$Y$2342,$D$2)*100-K15, "--") -> -2.0702 | L47: =IF( L78>$E$2, SUMIFS(IF($G$2="CPR",'Grid Data'!$AH$4:$AH$2342,'Grid Data'!$AI$4:$AI$2342),'Grid Data'!$Z$4:$Z$2342,$D47,'Grid Data'!$AA$4:$AA$2342,L$4,'Grid Data'!$Y$4:$Y$2342,$D$2)*100-L15, "--") -> -1.299 | ... AH47: =IF( AH78>$E$2, SUMIFS(IF($G$2="CPR",'Grid Data'!$AH$4:$AH$2342,'Grid Data'!$AI$4:$AI$2342),'Grid Data'!$Z$4:$Z$2342,$D47,'Grid Data'!$AA$4:$AA$2342,AH$4,'Grid Data'!$Y$4:$Y$2342,$D$2)*100-AH15, "--") -> --
D48: 4750 | E48: =IF( E79>$E$2, SUMIFS(IF($G$2="CPR",'Grid Data'!$AH$4:$AH$2342,'Grid Data'!$AI$4:$AI$2342),'Grid Data'!$Z$4:$Z$2342,$D48,'Grid Data'!$AA$4:$AA$2342,E$4,'Grid Data'!$Y$4:$Y$2342,$D$2)*100-E16, "--") -> -0.1527 | F48: =IF( F79>$E$2, SUMIFS(IF($G$2="CPR",'Grid Data'!$AH$4:$AH$2342,'Grid Data'!$AI$4:$AI$2342),'Grid Data'!$Z$4:$Z$2342,$D48,'Grid Data'!$AA$4:$AA$2342,F$4,'Grid Data'!$Y$4:$Y$2342,$D$2)*100-F16, "--") -> -1.718 | G48: =IF( G79>$E$2, SUMIFS(IF($G$2="CPR",'Grid Data'!$AH$4:$AH$2342,'Grid Data'!$AI$4:$AI$2342),'Grid Data'!$Z$4:$Z$2342,$D48,'Grid Data'!$AA$4:$AA$2342,G$4,'Grid Data'!$Y$4:$Y$2342,$D$2)*100-G16, "--") -> 0.1537 | H48: =IF( H79>$E$2, SUMIFS(IF($G$2="CPR",'Grid Data'!$AH$4:$AH$2342,'Grid Data'!$AI$4:$AI$2342),'Grid Data'!$Z$4:$Z$2342,$D48,'Grid Data'!$AA$4:$AA$2342,H$4,'Grid Data'!$Y$4:$Y$2342,$D$2)*100-H16, "--") -> 0 | I48: =IF( I79>$E$2, SUMIFS(IF($G$2="CPR",'Grid Data'!$AH$4:$AH$2342,'Grid Data'!$AI$4:$AI$2342),'Grid Data'!$Z$4:$Z$2342,$D48,'Grid Data'!$AA$4:$AA$2342,I$4,'Grid Data'!$Y$4:$Y$2342,$D$2)*100-I16, "--") -> 0 | J48: =IF( J79>$E$2, SUMIFS(IF($G$2="CPR",'Grid Data'!$AH$4:$AH$2342,'Grid Data'!$AI$4:$AI$2342),'Grid Data'!$Z$4:$Z$2342,$D48,'Grid Data'!$AA$4:$AA$2342,J$4,'Grid Data'!$Y$4:$Y$2342,$D$2)*100-J16, "--") -> -0.8078 | K48: =IF( K79>$E$2, SUMIFS(IF($G$2="CPR",'Grid Data'!$AH$4:$AH$2342,'Grid Data'!$AI$4:$AI$2342),'Grid Data'!$Z$4:$Z$2342,$D48,'Grid Data'!$AA$4:$AA$2342,K$4,'Grid Data'!$Y$4:$Y$2342,$D$2)*100-K16, "--") -> 0 | L48: =IF( L79>$E$2, SUMIFS(IF($G$2="CPR",'Grid Data'!$AH$4:$AH$2342,'Grid Data'!$AI$4:$AI$2342),'Grid Data'!$Z$4:$Z$2342,$D48,'Grid Data'!$AA$4:$AA$2342,L$4,'Grid Data'!$Y$4:$Y$2342,$D$2)*100-L16, "--") -> 0.2459 | ... AH48: =IF( AH79>$E$2, SUMIFS(IF($G$2="CPR",'Grid Data'!$AH$4:$AH$2342,'Grid Data'!$AI$4:$AI$2342),'Grid Data'!$Z$4:$Z$2342,$D48,'Grid Data'!$AA$4:$AA$2342,AH$4,'Grid Data'!$Y$4:$Y$2342,$D$2)*100-AH16, "--") -> --
D49: 5000 | E49: =IF( E80>$E$2, SUMIFS(IF($G$2="CPR",'Grid Data'!$AH$4:$AH$2342,'Grid Data'!$AI$4:$AI$2342),'Grid Data'!$Z$4:$Z$2342,$D49,'Grid Data'!$AA$4:$AA$2342,E$4,'Grid Data'!$Y$4:$Y$2342,$D$2)*100-E17, "--") -> -0.4526 | F49: =IF( F80>$E$2, SUMIFS(IF($G$2="CPR",'Grid Data'!$AH$4:$AH$2342,'Grid Data'!$AI$4:$AI$2342),'Grid Data'!$Z$4:$Z$2342,$D49,'Grid Data'!$AA$4:$AA$2342,F$4,'Grid Data'!$Y$4:$Y$2342,$D$2)*100-F17, "--") -> 0.2495 | G49: =IF( G80>$E$2, SUMIFS(IF($G$2="CPR",'Grid Data'!$AH$4:$AH$2342,'Grid Data'!$AI$4:$AI$2342),'Grid Data'!$Z$4:$Z$2342,$D49,'Grid Data'!$AA$4:$AA$2342,G$4,'Grid Data'!$Y$4:$Y$2342,$D$2)*100-G17, "--") -> 0.3157 | H49: =IF( H80>$E$2, SUMIFS(IF($G$2="CPR",'Grid Data'!$AH$4:$AH$2342,'Grid Data'!$AI$4:$AI$2342),'Grid Data'!$Z$4:$Z$2342,$D49,'Grid Data'!$AA$4:$AA$2342,H$4,'Grid Data'!$Y$4:$Y$2342,$D$2)*100-H17, "--") -> 0.7562 | I49: =IF( I80>$E$2, SUMIFS(IF($G$2="CPR",'Grid Data'!$AH$4:$AH$2342,'Grid Data'!$AI$4:$AI$2342),'Grid Data'!$Z$4:$Z$2342,$D49,'Grid Data'!$AA$4:$AA$2342,I$4,'Grid Data'!$Y$4:$Y$2342,$D$2)*100-I17, "--") -> -0.1876 | J49: =IF( J80>$E$2, SUMIFS(IF($G$2="CPR",'Grid Data'!$AH$4:$AH$2342,'Grid Data'!$AI$4:$AI$2342),'Grid Data'!$Z$4:$Z$2342,$D49,'Grid Data'!$AA$4:$AA$2342,J$4,'Grid Data'!$Y$4:$Y$2342,$D$2)*100-J17, "--") -> 1.4102 | K49: =IF( K80>$E$2, SUMIFS(IF($G$2="CPR",'Grid Data'!$AH$4:$AH$2342,'Grid Data'!$AI$4:$AI$2342),'Grid Data'!$Z$4:$Z$2342,$D49,'Grid Data'!$AA$4:$AA$2342,K$4,'Grid Data'!$Y$4:$Y$2342,$D$2)*100-K17, "--") -> -0.0857 | L49: =IF( L80>$E$2, SUMIFS(IF($G$2="CPR",'Grid Data'!$AH$4:$AH$2342,'Grid Data'!$AI$4:$AI$2342),'Grid Data'!$Z$4:$Z$2342,$D49,'Grid Data'!$AA$4:$AA$2342,L$4,'Grid Data'!$Y$4:$Y$2342,$D$2)*100-L17, "--") -> -1.0584 | ... AH49: =IF( AH80>$E$2, SUMIFS(IF($G$2="CPR",'Grid Data'!$AH$4:$AH$2342,'Grid Data'!$AI$4:$AI$2342),'Grid Data'!$Z$4:$Z$2342,$D49,'Grid Data'!$AA$4:$AA$2342,AH$4,'Grid Data'!$Y$4:$Y$2342,$D$2)*100-AH17, "--") -> --
D50: 5250 | E50: =IF( E81>$E$2, SUMIFS(IF($G$2="CPR",'Grid Data'!$AH$4:$AH$2342,'Grid Data'!$AI$4:$AI$2342),'Grid Data'!$Z$4:$Z$2342,$D50,'Grid Data'!$AA$4:$AA$2342,E$4,'Grid Data'!$Y$4:$Y$2342,$D$2)*100-E18, "--") -> -0.0856 | F50: =IF( F81>$E$2, SUMIFS(IF($G$2="CPR",'Grid Data'!$AH$4:$AH$2342,'Grid Data'!$AI$4:$AI$2342),'Grid Data'!$Z$4:$Z$2342,$D50,'Grid Data'!$AA$4:$AA$2342,F$4,'Grid Data'!$Y$4:$Y$2342,$D$2)*100-F18, "--") -> -0.7256 | G50: =IF( G81>$E$2, SUMIFS(IF($G$2="CPR",'Grid Data'!$AH$4:$AH$2342,'Grid Data'!$AI$4:$AI$2342),'Grid Data'!$Z$4:$Z$2342,$D50,'Grid Data'!$AA$4:$AA$2342,G$4,'Grid Data'!$Y$4:$Y$2342,$D$2)*100-G18, "--") -> -4.5129 | H50: =IF( H81>$E$2, SUMIFS(IF($G$2="CPR",'Grid Data'!$AH$4:$AH$2342,'Grid Data'!$AI$4:$AI$2342),'Grid Data'!$Z$4:$Z$2342,$D50,'Grid Data'!$AA$4:$AA$2342,H$4,'Grid Data'!$Y$4:$Y$2342,$D$2)*100-H18, "--") -> 0.4748 | I50: =IF( I81>$E$2, SUMIFS(IF($G$2="CPR",'Grid Data'!$AH$4:$AH$2342,'Grid Data'!$AI$4:$AI$2342),'Grid Data'!$Z$4:$Z$2342,$D50,'Grid Data'!$AA$4:$AA$2342,I$4,'Grid Data'!$Y$4:$Y$2342,$D$2)*100-I18, "--") -> -0.6806 | J50: =IF( J81>$E$2, SUMIFS(IF($G$2="CPR",'Grid Data'!$AH$4:$AH$2342,'Grid Data'!$AI$4:$AI$2342),'Grid Data'!$Z$4:$Z$2342,$D50,'Grid Data'!$AA$4:$AA$2342,J$4,'Grid Data'!$Y$4:$Y$2342,$D$2)*100-J18, "--") -> 1.4314 | K50: =IF( K81>$E$2, SUMIFS(IF($G$2="CPR",'Grid Data'!$AH$4:$AH$2342,'Grid Data'!$AI$4:$AI$2342),'Grid Data'!$Z$4:$Z$2342,$D50,'Grid Data'!$AA$4:$AA$2342,K$4,'Grid Data'!$Y$4:$Y$2342,$D$2)*100-K18, "--") -> 1.1637 | L50: =IF( L81>$E$2, SUMIFS(IF($G$2="CPR",'Grid Data'!$AH$4:$AH$2342,'Grid Data'!$AI$4:$AI$2342),'Grid Data'!$Z$4:$Z$2342,$D50,'Grid Data'!$AA$4:$AA$2342,L$4,'Grid Data'!$Y$4:$Y$2342,$D$2)*100-L18, "--") -> 2.7914 | ... AH50: =IF( AH81>$E$2, SUMIFS(IF($G$2="CPR",'Grid Data'!$AH$4:$AH$2342,'Grid Data'!$AI$4:$AI$2342),'Grid Data'!$Z$4:$Z$2342,$D50,'Grid Data'!$AA$4:$AA$2342,AH$4,'Grid Data'!$Y$4:$Y$2342,$D$2)*100-AH18, "--") -> --
... D65: 20000 | E65: =IF( E96>$E$2, SUMIFS(IF($G$2="CPR",'Grid Data'!$AH$4:$AH$2342,'Grid Data'!$AI$4:$AI$2342),'Grid Data'!$Z$4:$Z$2342,$D65,'Grid Data'!$AA$4:$AA$2342,E$4,'Grid Data'!$Y$4:$Y$2342,$D$2)*100-E33, "--") -> -- | F65: =IF( F96>$E$2, SUMIFS(IF($G$2="CPR",'Grid Data'!$AH$4:$AH$2342,'Grid Data'!$AI$4:$AI$2342),'Grid Data'!$Z$4:$Z$2342,$D65,'Grid Data'!$AA$4:$AA$2342,F$4,'Grid Data'!$Y$4:$Y$2342,$D$2)*100-F33, "--") -> -- | G65: =IF( G96>$E$2, SUMIFS(IF($G$2="CPR",'Grid Data'!$AH$4:$AH$2342,'Grid Data'!$AI$4:$AI$2342),'Grid Data'!$Z$4:$Z$2342,$D65,'Grid Data'!$AA$4:$AA$2342,G$4,'Grid Data'!$Y$4:$Y$2342,$D$2)*100-G33, "--") -> -- | H65: =IF( H96>$E$2, SUMIFS(IF($G$2="CPR",'Grid Data'!$AH$4:$AH$2342,'Grid Data'!$AI$4:$AI$2342),'Grid Data'!$Z$4:$Z$2342,$D65,'Grid Data'!$AA$4:$AA$2342,H$4,'Grid Data'!$Y$4:$Y$2342,$D$2)*100-H33, "--") -> -- | I65: =IF( I96>$E$2, SUMIFS(IF($G$2="CPR",'Grid Data'!$AH$4:$AH$2342,'Grid Data'!$AI$4:$AI$2342),'Grid Data'!$Z$4:$Z$2342,$D65,'Grid Data'!$AA$4:$AA$2342,I$4,'Grid Data'!$Y$4:$Y$2342,$D$2)*100-I33, "--") -> -- | J65: =IF( J96>$E$2, SUMIFS(IF($G$2="CPR",'Grid Data'!$AH$4:$AH$2342,'Grid Data'!$AI$4:$AI$2342),'Grid Data'!$Z$4:$Z$2342,$D65,'Grid Data'!$AA$4:$AA$2342,J$4,'Grid Data'!$Y$4:$Y$2342,$D$2)*100-J33, "--") -> -- | K65: =IF( K96>$E$2, SUMIFS(IF($G$2="CPR",'Grid Data'!$AH$4:$AH$2342,'Grid Data'!$AI$4:$AI$2342),'Grid Data'!$Z$4:$Z$2342,$D65,'Grid Data'!$AA$4:$AA$2342,K$4,'Grid Data'!$Y$4:$Y$2342,$D$2)*100-K33, "--") -> -- | L65: =IF( L96>$E$2, SUMIFS(IF($G$2="CPR",'Grid Data'!$AH$4:$AH$2342,'Grid Data'!$AI$4:$AI$2342),'Grid Data'!$Z$4:$Z$2342,$D65,'Grid Data'!$AA$4:$AA$2342,L$4,'Grid Data'!$Y$4:$Y$2342,$D$2)*100-L33, "--") -> -- | ... AH65: =IF( AH96>$E$2, SUMIFS(IF($G$2="CPR",'Grid Data'!$AH$4:$AH$2342,'Grid Data'!$AI$4:$AI$2342),'Grid Data'!$Z$4:$Z$2342,$D65,'Grid Data'!$AA$4:$AA$2342,AH$4,'Grid Data'!$Y$4:$Y$2342,$D$2)*100-AH33, "--") -> --
C67: Apr | D67: Ln Count | E67: 5 | F67: 6 | G67: 7 | H67: 8 | I67: 9 | J67: 10 | K67: 12 | L67: 14 | M67: 16 | N67: 18 | O67: 20 | P67: 24 | Q67: 30 | R67: 36 | S67: 42 | T67: 48 | U67: 54 | V67: 60 | W67: 72 | X67: 84 | Y67: 96 | Z67: 108 | AA67: 120 | AB67: 144 | AC67: 168 | AD67: 192 | AE67: 216 | AF67: 240 | AG67: 320 | AH67: 360
D68: 2000 | E68: =SUMIFS('Grid Data'!$P$4:$P$2342,'Grid Data'!$N$4:$N$2342,$D68,'Grid Data'!$O$4:$O$2342,E$4,'Grid Data'!$M$4:$M$2342,$D$2) -> 0 | F68: =SUMIFS('Grid Data'!$P$4:$P$2342,'Grid Data'!$N$4:$N$2342,$D68,'Grid Data'!$O$4:$O$2342,F$4,'Grid Data'!$M$4:$M$2342,$D$2) -> 0 | G68: =SUMIFS('Grid Data'!$P$4:$P$2342,'Grid Data'!$N$4:$N$2342,$D68,'Grid Data'!$O$4:$O$2342,G$4,'Grid Data'!$M$4:$M$2342,$D$2) -> 0 | H68: =SUMIFS('Grid Data'!$P$4:$P$2342,'Grid Data'!$N$4:$N$2342,$D68,'Grid Data'!$O$4:$O$2342,H$4,'Grid Data'!$M$4:$M$2342,$D$2) -> 0 | I68: =SUMIFS('Grid Data'!$P$4:$P$2342,'Grid Data'!$N$4:$N$2342,$D68,'Grid Data'!$O$4:$O$2342,I$4,'Grid Data'!$M$4:$M$2342,$D$2) -> 0 | J68: =SUMIFS('Grid Data'!$P$4:$P$2342,'Grid Data'!$N$4:$N$2342,$D68,'Grid Data'!$O$4:$O$2342,J$4,'Grid Data'!$M$4:$M$2342,$D$2) -> 0 | K68: =SUMIFS('Grid Data'!$P$4:$P$2342,'Grid Data'!$N$4:$N$2342,$D68,'Grid Data'!$O$4:$O$2342,K$4,'Grid Data'!$M$4:$M$2342,$D$2) -> 0 | L68: =SUMIFS('Grid Data'!$P$4:$P$2342,'Grid Data'!$N$4:$N$2342,$D68,'Grid Data'!$O$4:$O$2342,L$4,'Grid Data'!$M$4:$M$2342,$D$2) -> 0 | ... AH68: =SUMIFS('Grid Data'!$P$4:$P$2342,'Grid Data'!$N$4:$N$2342,$D68,'Grid Data'!$O$4:$O$2342,AH$4,'Grid Data'!$M$4:$M$2342,$D$2) -> 0
D69: 2250 | E69: =SUMIFS('Grid Data'!$P$4:$P$2342,'Grid Data'!$N$4:$N$2342,$D69,'Grid Data'!$O$4:$O$2342,E$4,'Grid Data'!$M$4:$M$2342,$D$2) -> 0 | F69: =SUMIFS('Grid Data'!$P$4:$P$2342,'Grid Data'!$N$4:$N$2342,$D69,'Grid Data'!$O$4:$O$2342,F$4,'Grid Data'!$M$4:$M$2342,$D$2) -> 0 | G69: =SUMIFS('Grid Data'!$P$4:$P$2342,'Grid Data'!$N$4:$N$2342,$D69,'Grid Data'!$O$4:$O$2342,G$4,'Grid Data'!$M$4:$M$2342,$D$2) -> 0 | H69: =SUMIFS('Grid Data'!$P$4:$P$2342,'Grid Data'!$N$4:$N$2342,$D69,'Grid Data'!$O$4:$O$2342,H$4,'Grid Data'!$M$4:$M$2342,$D$2) -> 0 | I69: =SUMIFS('Grid Data'!$P$4:$P$2342,'Grid Data'!$N$4:$N$2342,$D69,'Grid Data'!$O$4:$O$2342,I$4,'Grid Data'!$M$4:$M$2342,$D$2) -> 0 | J69: =SUMIFS('Grid Data'!$P$4:$P$2342,'Grid Data'!$N$4:$N$2342,$D69,'Grid Data'!$O$4:$O$2342,J$4,'Grid Data'!$M$4:$M$2342,$D$2) -> 0 | K69: =SUMIFS('Grid Data'!$P$4:$P$2342,'Grid Data'!$N$4:$N$2342,$D69,'Grid Data'!$O$4:$O$2342,K$4,'Grid Data'!$M$4:$M$2342,$D$2) -> 0 | L69: =SUMIFS('Grid Data'!$P$4:$P$2342,'Grid Data'!$N$4:$N$2342,$D69,'Grid Data'!$O$4:$O$2342,L$4,'Grid Data'!$M$4:$M$2342,$D$2) -> 0 | ... AH69: =SUMIFS('Grid Data'!$P$4:$P$2342,'Grid Data'!$N$4:$N$2342,$D69,'Grid Data'!$O$4:$O$2342,AH$4,'Grid Data'!$M$4:$M$2342,$D$2) -> 0
D70: 2500 | E70: =SUMIFS('Grid Data'!$P$4:$P$2342,'Grid Data'!$N$4:$N$2342,$D70,'Grid Data'!$O$4:$O$2342,E$4,'Grid Data'!$M$4:$M$2342,$D$2) -> 0 | F70: =SUMIFS('Grid Data'!$P$4:$P$2342,'Grid Data'!$N$4:$N$2342,$D70,'Grid Data'!$O$4:$O$2342,F$4,'Grid Data'!$M$4:$M$2342,$D$2) -> 0 | G70: =SUMIFS('Grid Data'!$P$4:$P$2342,'Grid Data'!$N$4:$N$2342,$D70,'Grid Data'!$O$4:$O$2342,G$4,'Grid Data'!$M$4:$M$2342,$D$2) -> 0 | H70: =SUMIFS('Grid Data'!$P$4:$P$2342,'Grid Data'!$N$4:$N$2342,$D70,'Grid Data'!$O$4:$O$2342,H$4,'Grid Data'!$M$4:$M$2342,$D$2) -> 0 | I70: =SUMIFS('Grid Data'!$P$4:$P$2342,'Grid Data'!$N$4:$N$2342,$D70,'Grid Data'!$O$4:$O$2342,I$4,'Grid Data'!$M$4:$M$2342,$D$2) -> 0 | J70: =SUMIFS('Grid Data'!$P$4:$P$2342,'Grid Data'!$N$4:$N$2342,$D70,'Grid Data'!$O$4:$O$2342,J$4,'Grid Data'!$M$4:$M$2342,$D$2) -> 0 | K70: =SUMIFS('Grid Data'!$P$4:$P$2342,'Grid Data'!$N$4:$N$2342,$D70,'Grid Data'!$O$4:$O$2342,K$4,'Grid Data'!$M$4:$M$2342,$D$2) -> 6 | L70: =SUMIFS('Grid Data'!$P$4:$P$2342,'Grid Data'!$N$4:$N$2342,$D70,'Grid Data'!$O$4:$O$2342,L$4,'Grid Data'!$M$4:$M$2342,$D$2) -> 1 | ... AH70: =SUMIFS('Grid Data'!$P$4:$P$2342,'Grid Data'!$N$4:$N$2342,$D70,'Grid Data'!$O$4:$O$2342,AH$4,'Grid Data'!$M$4:$M$2342,$D$2) -> 0
D71: 2750 | E71: =SUMIFS('Grid Data'!$P$4:$P$2342,'Grid Data'!$N$4:$N$2342,$D71,'Grid Data'!$O$4:$O$2342,E$4,'Grid Data'!$M$4:$M$2342,$D$2) -> 6 | F71: =SUMIFS('Grid Data'!$P$4:$P$2342,'Grid Data'!$N$4:$N$2342,$D71,'Grid Data'!$O$4:$O$2342,F$4,'Grid Data'!$M$4:$M$2342,$D$2) -> 0 | G71: =SUMIFS('Grid Data'!$P$4:$P$2342,'Grid Data'!$N$4:$N$2342,$D71,'Grid Data'!$O$4:$O$2342,G$4,'Grid Data'!$M$4:$M$2342,$D$2) -> 0 | H71: =SUMIFS('Grid Data'!$P$4:$P$2342,'Grid Data'!$N$4:$N$2342,$D71,'Grid Data'!$O$4:$O$2342,H$4,'Grid Data'!$M$4:$M$2342,$D$2) -> 1 | I71: =SUMIFS('Grid Data'!$P$4:$P$2342,'Grid Data'!$N$4:$N$2342,$D71,'Grid Data'!$O$4:$O$2342,I$4,'Grid Data'!$M$4:$M$2342,$D$2) -> 0 | J71: =SUMIFS('Grid Data'!$P$4:$P$2342,'Grid Data'!$N$4:$N$2342,$D71,'Grid Data'!$O$4:$O$2342,J$4,'Grid Data'!$M$4:$M$2342,$D$2) -> 0 | K71: =SUMIFS('Grid Data'!$P$4:$P$2342,'Grid Data'!$N$4:$N$2342,$D71,'Grid Data'!$O$4:$O$2342,K$4,'Grid Data'!$M$4:$M$2342,$D$2) -> 12 | L71: =SUMIFS('Grid Data'!$P$4:$P$2342,'Grid Data'!$N$4:$N$2342,$D71,'Grid Data'!$O$4:$O$2342,L$4,'Grid Data'!$M$4:$M$2342,$D$2) -> 1 | ... AH71: =SUMIFS('Grid Data'!$P$4:$P$2342,'Grid Data'!$N$4:$N$2342,$D71,'Grid Data'!$O$4:$O$2342,AH$4,'Grid Data'!$M$4:$M$2342,$D$2) -> 0
D72: 3000 | E72: =SUMIFS('Grid Data'!$P$4:$P$2342,'Grid Data'!$N$4:$N$2342,$D72,'Grid Data'!$O$4:$O$2342,E$4,'Grid Data'!$M$4:$M$2342,$D$2) -> 18 | F72: =SUMIFS('Grid Data'!$P$4:$P$2342,'Grid Data'!$N$4:$N$2342,$D72,'Grid Data'!$O$4:$O$2342,F$4,'Grid Data'!$M$4:$M$2342,$D$2) -> 1 | G72: =SUMIFS('Grid Data'!$P$4:$P$2342,'Grid Data'!$N$4:$N$2342,$D72,'Grid Data'!$O$4:$O$2342,G$4,'Grid Data'!$M$4:$M$2342,$D$2) -> 0 | H72: =SUMIFS('Grid Data'!$P$4:$P$2342,'Grid Data'!$N$4:$N$2342,$D72,'Grid Data'!$O$4:$O$2342,H$4,'Grid Data'!$M$4:$M$2342,$D$2) -> 0 | I72: =SUMIFS('Grid Data'!$P$4:$P$2342,'Grid Data'!$N$4:$N$2342,$D72,'Grid Data'!$O$4:$O$2342,I$4,'Grid Data'!$M$4:$M$2342,$D$2) -> 0 | J72: =SUMIFS('Grid Data'!$P$4:$P$2342,'Grid Data'!$N$4:$N$2342,$D72,'Grid Data'!$O$4:$O$2342,J$4,'Grid Data'!$M$4:$M$2342,$D$2) -> 0 | K72: =SUMIFS('Grid Data'!$P$4:$P$2342,'Grid Data'!$N$4:$N$2342,$D72,'Grid Data'!$O$4:$O$2342,K$4,'Grid Data'!$M$4:$M$2342,$D$2) -> 10 | L72: =SUMIFS('Grid Data'!$P$4:$P$2342,'Grid Data'!$N$4:$N$2342,$D72,'Grid Data'!$O$4:$O$2342,L$4,'Grid Data'!$M$4:$M$2342,$D$2) -> 1 | ... AH72: =SUMIFS('Grid Data'!$P$4:$P$2342,'Grid Data'!$N$4:$N$2342,$D72,'Grid Data'!$O$4:$O$2342,AH$4,'Grid Data'!$M$4:$M$2342,$D$2) -> 4
